File: Scripts/Data_examples/Nb-PrO2/Jan 31 2019 Pr0.996Nb0.004O2 1300C 10h air.dat
Comment,Time Stamp (sec),Temperature (K),Magnetic Field (Oe),Frequency (Hz),AC Voltage (Vrms),Re[Impedance] (Ohm),-Im[Impedance] (Ohm),Re[Cp] (F),Im[Cp] (F),Re[Modulus],Im[Modulus],Re[Permittivity],Im[Permittivity],Loss Factor,Re[Sp.Impedance] (Ohm-cm),-Im[Sp.Impedance] (Ohm-cm)
,681993.767,360.0078,-0.019,5.000000e+05,0.5,5124.682,1079.842,1.25316853705999E-11,-5.94724991696717E-11,0.000511675224992916,0.00242829304228503,83.0854891998019,394.304639904189,4.74577021453138,8729.76378897739,1839.48303317492
,682023.61,360.0078,-0.019,2.298591e+01,0.5,10229.02,414.4991,2.73844422832849E-08,-6.75794007283893E-07,9.02915259369517E-09,2.22821671902206E-07,181559.75962406,4480536.65831772,24.6780270451733,17424.8720979615,706.088540468212
,685826.056,359.9998,-0.019,6.972812e+01,0.5,9651.684,981.7493,2.38088990253756E-08,-2.34067872297778E-07,6.48738455558105E-08,6.37781821865814E-07,157853.789361241,1551877.74833887,9.83110861398119,16441.3950925838,1672.384645329
,685929.344,357.9533,-0.019,2.115173e+02,0.5,9032.389,1244.407,1.1263171590661E-08,-8.17524710007245E-08,2.49446335997085E-07,1.8105783247365E-06,74675.2008111244,542021.591311517,7.25838813185718,15386.442011457,2119.81527192321
,686063.068,355.9741,-0.019,6.416440e+02,0.5,9009.126,651.5844,1.98090434374321E-09,-2.73889565599328E-08,3.96215082217104E-07,5.47826436420861E-06,13133.4614292218,181589.6894278,13.8264912419634,15346.8140901493,1109.95724233866
,686181.66,353.9804,-0.019,1.946446e+03,0.5,9633.749,318.8124,2.80574063110905E-10,-8.47827782081442E-09,5.88086447735123E-07,1.7770567354914E-05,1860.21533424675,56211.2628495138,30.2176107328322,16410.8432820411,543.088711650201
,686298.77,351.9776,-0.019,5.904585e+03,0.5,10426.11,365.5803,9.05393234803601E-11,-2.58212202881779E-09,2.045664426857E-06,5.83410056217419E-05,600.278714372537,17119.5546004712,28.5193430827646,17760.6098364533,622.756624684905
,686414.18,349.9815,-0.019,1.791157e+04,0.5,11123.48,911.7051,6.50357764453805E-11,-7.93484821544446E-10,1.54757474507213E-05,0.000188815623882272,431.1893525615,5260.8306561308,12.2007434202134,18948.561669078,1553.06615477917
,686530.432,347.9672,-0.019,5.433485e+04,0.5,10842.28,2043.145,4.91637320455079E-11,-2.60895310260588E-10,0.000105206380694606,0.000558294706091595,325.957172326731,1729.74455086382,5.30666203328692,18469.5447120336,3480.44488158098
,686646.668,345.9699,-0.019,1.648255e+05,0.5,9642.339,2117.958,2.09838276878964E-11,-9.55321966178192E-11,0.000330830755101076,0.00150615937252323,139.123472795085,633.381628694944,4.55265826801098,16425.4761257858,3607.88690009936
,686762.624,343.9789,-0.019,5.000000e+05,0.5,9338.07,2181.951,7.55255642702824E-12,-3.23225868016924E-11,0.00103390150489472,0.00442477609525246,50.0736993382328,214.299821388918,4.27968822397937,15907.1617214368,3716.89732731182
,686791.765,343.9789,-0.019,2.298591e+01,0.5,19227.99,1067.983,1.99397501112606E-08,-3.58995710364133E-07,2.32641795228804E-08,4.18848812410075E-07,132201.203870201,2380153.45375739,18.0040225359392,32754.3857037021,1819.28153213086
,686907.985,341.9820,-0.019,6.972812e+01,0.5,19416.47,2221.567,1.32765609865872E-08,-1.16036990151204E-07,1.46800812030001E-07,1.28303740681967E-06,88024.0392125961,769329.089174531,8.73998848560498,33075.4565289643,3784.38216291023
,687025.345,339.9755,-0.019,2.115173e+02,0.5,18944.14,1739.256,3.61607977062253E-09,-3.93866811014831E-08,3.48640787588744E-07,3.79742826230953E-06,23974.7286851407,261135.000640114,10.8920940908066,32270.8545399145,2962.77779744414
,687141.535,337.9767,-0.019,6.416440e+02,0.5,20031.22,813.3214,5.0194484129331E-10,-1.2362354591692E-08,4.9456402788331E-07,1.21805731985126E-05,3327.91092792774,81962.8205254709,24.6289105389333,34122.667319658,1385.47205592862
,687258.847,335.9679,-0.019,1.946446e+03,0.5,21640.71,640.6185,1.11751765252543E-10,-3.77508227411221E-09,1.18169512233026E-06,3.9918799489499E-05,740.917906120752,25028.9205512585,33.7809632409929,36864.3920785252,1091.27711414074
,687375.13,333.9744,-0.019,5.904585e+03,0.5,23464.8,1390.705,6.784395211927E-11,-1.14470341854545E-09,7.78191753426585E-06,0.000131301130403674,449.807650318278,7589.4215906237,16.8725933968742,39971.6824098737,2369.03014668028
,687490.415,331.9907,-0.019,1.791157e+04,0.5,24061.65,3637.893,5.45846556261881E-11,-3.61032300578348E-10,6.17514515611975E-05,0.000408434721542796,361.89807526962,2393.6561143528,6.61417199461337,40988.4010116233,6197.05702316247
,687608.274,329.9753,-0.019,5.433485e+04,0.5,21704.94,4855.729,2.87520809426963E-11,-1.28520803310145E-10,0.000250032999970065,0.00111763882670764,190.627249247789,852.097184024955,4.4699652719499,36973.8062291332,8271.60928098317
,687724.682,327.9804,-0.019,1.648255e+05,0.5,20682.04,4440.374,9.58202965421302E-12,-4.46304569366499E-11,0.000693598401550543,0.0032305904603541,63.529174073829,295.901408161091,4.65772477723723,35231.3224262855,7564.06273691064
,687840.466,325.9839,-0.019,5.000000e+05,0.5,19603.21,7638.883,5.49326970114551E-12,-1.40970505161805E-11,0.00361962877691326,0.00928883752190912,36.4205601185051,93.4639119777957,2.56624037833804,33393.5633090442,13012.640433423
,687869.622,325.9839,-0.019,2.298591e+01,0.5,42375.32,3091.091,1.18561021373168E-08,-1.62533591544696E-07,6.73341204359619E-08,9.23073730405357E-07,78606.3499800929,1077603.09691252,13.7088555464721,72185.266145749,5265.59390031106
,687985.937,323.9883,-0.019,6.972812e+01,0.5,42254.35,4081.461,5.16957469292973E-09,-5.35193202694318E-08,2.69702326812012E-07,2.79216107000144E-06,34274.4514895542,354834.866558236,10.352751134949,71979.1968666108,6952.66368604402
,688103.203,321.9813,-0.019,2.115173e+02,0.5,43939.5,2179.179,8.47198922906455E-10,-1.70823493953678E-08,4.3682510387019E-07,8.80784765799607E-06,5616.9569277862,113256.542454044,20.1633275651059,74849.8064866799,3712.17529671108
,688220.047,319.9793,-0.019,6.416440e+02,0.5,47955.73,1359.051,1.46463719555472E-10,-5.16814644174348E-09,8.26410981758061E-07,2.91608938223985E-05,971.059313206042,34264.9821368693,35.2861886713597,81691.350844399,2315.10837300217
,688339.482,317.9694,-0.019,1.946446e+03,0.5,52339.28,2367.792,7.05307463444358E-11,-1.559059445057E-09,4.36766696105811E-06,9.6545872281674E-05,467.621185048477,10336.6157746052,22.1046781136181,89158.615360943,4033.47268404758
,688455.827,315.9729,-0.019,5.904585e+03,0.5,55522.41,6629.156,5.71487821247229E-11,-4.78648882622394E-10,3.70945278213451E-05,0.000310684736104133,378.898318908098,3173.45795011102,8.37548701523995,94580.9953270771,11292.5964967743
,688572.36,313.9791,-0.019,1.791157e+04,0.5,51813.4,11240.48,3.55315903271995E-11,-1.63784153546763E-10,0.000190801641566866,0.000879507082896872,235.575621081923,1085.89436441914,4.60953624756238,88262.7923261972,19147.8681554728
,688686.116,311.9854,-0.019,5.433485e+04,0.5,48251.89,10206.52,1.22908212748945E-11,-5.81055400044155E-11,0.000525557916196408,0.00248460422954526,81.4885522651016,385.241655349221,4.72755552333214,82195.8517761141,17386.543927501
,688803.366,309.9759,-0.019,1.648255e+05,0.5,47518.94,15252.64,5.91317379156494E-12,-1.84222371085233E-11,0.00238250352862752,0.00742258666215417,39.2045381500112,122.140042384669,3.11545673404735,80947.2903299344,25982.4793730241
,688920.508,307.9736,-0.019,5.000000e+05,0.5,31642.41,27452.34,4.97947761014317E-12,-5.73949878684186E-12,0.0130080903003236,0.0149935242897277,33.0141015324901,38.053067114595,1.15263070470495,53902.0304116384,46764.3540915701
,688954.141,307.9736,-0.019,2.298591e+01,0.5,100010.9,7899.422,5.43451155938576E-09,-6.88038178128189E-08,1.72075371550849E-07,2.17856607440834E-06,36030.9916918964,456171.591668236,12.6605338972902,170365.992138251,13456.4619091392
,689074.137,305.9911,-0.019,6.972812e+01,0.5,102571.5,5800.038,1.25431394539402E-09,-2.21820724019365E-08,3.83265635564835E-07,6.77790923754956E-06,8316.14301518385,147067.874948738,17.6846255145225,174727.908284084,9880.21533962357
,689196.676,303.9705,-0.019,2.115173e+02,0.5,112481.7,3244.806,1.92811686383736E-10,-6.68384681990524E-09,6.5043427730747E-07,2.2547404451858E-05,1278.3478688521,44314.125861411,34.6651540954991,191609.678723991,5527.44344352617
,689312.694,301.9699,-0.019,6.416440e+02,0.5,124415,4578.906,7.32744156870293E-11,-1.99096387383837E-09,2.78433863250009E-06,7.56542045114048E-05,485.811803691576,13200.1564470394,27.1713374330026,211937.747904284,7800.04843069897
,689426.528,299.9714,-0.019,1.946446e+03,0.5,134619.8,12937.81,5.7840003076441E-11,-6.01833667842538E-10,2.3865291075165E-05,0.000248321834335216,383.48113671913,3990.17715740933,10.405145847713,229321.361856087,22039.2260918179
,689539.208,297.9869,-0.019,5.904585e+03,0.5,130201.9,26426.17,4.03553040312151E-11,-1.988308279233E-10,0.000147871961117915,0.000728566050028388,267.557002756105,1318.25497668221,4.92700607011913,221795.582999307,45016.2999279488
,689653.385,295.9771,-0.019,1.791157e+04,0.5,119951.5,25598.53,1.51199007915304E-11,-7.08499581731943E-11,0.000434522506663297,0.00203611795122698,100.245443191863,469.737570049092,4.68587454045213,204334.290622037,43606.4365057288
,689767.047,293.9801,-0.019,5.433485e+04,0.5,119381.4,33907.21,6.44862512809255E-12,-2.27044895721844E-11,0.00174596264266704,0.00614723135962206,42.7545982514606,150.531518095913,3.52082639650977,203363.139956279,57760.0588764829
,689883.377,291.9874,-0.019,1.648255e+05,0.5,89978.91,65690.52,5.11064827815296E-12,-7.00025759366161E-12,0.0102610364958051,0.0140549485582206,33.8837674072675,46.4119397745589,1.36973965193151,153276.755570327,111902.108808916
,689998.131,289.9914,-0.019,5.000000e+05,0.5,26813.76,54328.93,4.71132422877382E-12,-2.32524949695358E-12,0.0257433656788441,0.0127055038430678,31.2362357297048,15.4164812036558,0.49354478359872,45676.549509673,92547.9328879113
,690046.928,289.9914,-0.019,2.298591e+01,0.5,259330.4,14600.97,1.49851543933459E-09,-2.66153966680854E-08,3.18057110729469E-07,5.64906836657548E-06,9935.20701075584,176460.961715702,17.7611761410372,441762.656746511,24872.3763132903
,690162.432,287.9844,-0.019,6.972812e+01,0.5,282241.3,8474.571,2.42605413870935E-10,-8.07985057862762E-09,5.59998372502787E-07,1.865046250165E-05,1608.4819318299,53569.6770333488,33.3044941153953,480790.784773358,14436.2134163481
,690278.683,285.9893,-0.019,2.115173e+02,0.5,314723.5,10062.31,7.63598832332268E-11,-2.38834320456758E-09,2.01703008836082E-06,6.30875782016483E-05,506.268555748834,15834.7945755217,31.2774601458313,536123.375819265,17140.8859069626
,690394.967,283.9706,-0.019,6.416440e+02,0.5,346946.5,28068.88,5.74633236826074E-11,-7.10277682260487E-10,1.70681090537803E-05,0.00021097103617342,380.983739858085,4709.16456590619,12.360539501398,591014.426341467,47814.6141011582
,690508.052,281.9756,-0.019,1.946446e+03,0.5,346704.5,65167.12,4.28163159284132E-11,-2.27792933089609E-10,0.000120208310937493,0.000639536661117265,283.873593171386,1510.27469349096,5.32023664694711,590602.185574736,111010.510390292
,690624.491,279.9787,-0.019,5.904585e+03,0.5,320075.9,69247.88,1.74047093907274E-11,-8.0447632800824E-11,0.000387487850825831,0.00179103710600445,115.393799903528,533.370470815014,4.62217615903909,545241.05135584,117961.979940892
,690736.141,277.9870,-0.019,1.791157e+04,0.5,318721.9,84959.95,6.93849132001926E-12,-2.60293130663336E-11,0.00144215353147186,0.00541014811852433,46.0024273339048,172.575208018296,3.75143700061029,542934.547231237,144727.086485235
,690850.646,275.9904,-0.019,5.433485e+04,0.5,255394.1,168687.2,5.27435820771389E-12,-7.98543083017978E-12,0.00868610391406735,0.0131508477918876,34.9691696642014,52.9436709728778,1.51400995451937,435057.27108501,287354.300271507
,690964.167,273.9785,-0.019,1.648255e+05,0.5,84815.73,154419.6,4.80384271063472E-12,-2.63853439788513E-12,0.0241207582352465,0.0132484459089127,31.8496363297127,17.4935704764104,0.549254952091574,144481.411429955,263049.811166502
,691078.048,271.9693,-0.019,5.000000e+05,0.5,14599.16,67898.72,4.48085600737062E-12,-9.63445758455607E-13,0.0321733113110353,0.00691770506954497,29.7082237860587,6.38767729890161,0.215013773455523,24869.293024911,115663.720631624
,691136.814,271.9693,-0.019,2.298591e+01,0.5,767054.4,23169.33,2.72411843285478E-10,-9.01859065429326E-09,5.04704150295331E-07,1.67089656534002E-05,1806.09954637811,59793.5548368182,33.1064558189641,1306657.41314208,39468.3568753861
,691255.453,269.9747,-0.019,6.972812e+01,0.5,863538.5,25465.96,7.78815114233486E-11,-2.6409247305914E-09,1.68278679289147E-06,5.70624937349039E-05,516.357001063067,17509.4184614481,33.9095207877496,1471015.59232121,43380.6069253754
,691367.352,267.9868,-0.019,2.115173e+02,0.5,959247,69360.81,5.64232543936022E-11,-7.80323031223248E-10,1.39036504265003E-05,0.000192284879035714,374.088046012992,5173.56755023225,13.8298125411165,1634052.55687771,118154.353287119
,691483.885,265.9691,-0.019,6.416440e+02,0.5,983812.3,174578.8,4.33736922920413E-11,-2.44425852241655E-10,0.000106157780320344,0.000598236040228554,287.569016928919,1620.55149854151,5.63534804913311,1675898.91269167,297390.48911974
,691597.157,263.9738,-0.019,1.946446e+03,0.5,913326.2,198773.4,1.8603145724644E-11,-8.54779381584021E-11,0.000366660590084428,0.00168473610368172,123.339472503311,566.721561996994,4.59481097571405,1555827.65687399,338605.367031929
,691707.965,261.9892,-0.019,5.904585e+03,0.5,911487.8,241338,7.31695262033461E-12,-2.76347406815878E-11,0.00135044629442236,0.00510037922714696,48.5116382939617,183.219246297553,3.77681011693144,1552695.98982623,411113.066782334
,691821.424,259.9722,-0.019,1.791157e+04,0.5,742350.9,476783.9,5.44253818162848E-12,-8.47401331591999E-12,0.00809317313785998,0.0126010428681551,36.0842084632991,56.1829890407745,1.55699657643641,1264575.63718779,812189.092979314
,691932.434,257.9850,-0.019,5.433485e+04,0.5,258568.1,449123.4,4.89836046252727E-12,-2.82007073759861E-12,0.0231264288140371,0.0133142845779819,32.4762921562691,18.6971624232703,0.575717275029535,440464.098331308,765070.143689385
,692042.821,255.9778,-0.019,1.648255e+05,0.5,46653.15,203174,4.51452690648051E-12,-1.03663313685349E-12,0.0317363270834011,0.00728734792774161,29.9314629627224,6.87291204248247,0.229621654345536,79472.4393653558,346101.67578431
,692155.781,253.9887,-0.019,5.000000e+05,0.5,6997.311,73189.98,4.30969921829396E-12,-4.12027790509845E-13,0.0346805361189202,0.00331562458236521,28.5734486038103,2.7317579021524,0.0956047672099378,11919.7390565918,124677.245753001
,692223.735,253.9887,-0.019,2.298591e+01,0.5,2542538,71825.89,7.68706517996816E-11,-2.72111564904325E-09,1.56460393035344E-06,5.53848333501051E-05,509.654968266925,18041.0869076241,35.3986285446654,4331147.9940607,122353.55357329
,692338.287,251.9726,-0.019,6.972812e+01,0.5,2862607,198111.3,5.49194194624289E-11,-7.93557533513157E-10,1.30911648004851E-05,0.000189160638469497,364.117570595103,5261.31273889241,14.4494887469821,4876377.29144427,337477.496735843
,692449.687,249.9717,-0.019,2.115173e+02,0.5,2962688,512273.2,4.26388529150226E-11,-2.46598139166957E-10,0.000102687201831476,0.000593882601353521,282.697007513002,1634.95383282725,5.7834140064325,5046862.69712693,872644.201420414
,692562.944,247.9800,-0.019,6.416440e+02,0.5,2778364,606606.7,1.86049623584684E-11,-8.52139576403026E-11,0.000368865067232957,0.00168946604720592,123.351516845755,564.971362415941,4.58017361166634,4732871.51081733,1033338.88889322
,692676.091,245.9725,-0.019,1.946446e+03,0.5,2790188,764823.7,7.4715171656812E-12,-2.725718036389E-11,0.00141080601907778,0.00514682537264287,49.5364063505548,180.716008882102,3.64814531767256,4753013.3902629,1302857.47314891
,692788.771,243.9901,-0.019,5.904585e+03,0.5,2222824,1491714,5.61089224713884E-12,-8.36086940818021E-12,0.00834712993245142,0.0124381756455804,37.2004014954446,55.4328411838397,1.49011405671597,3786523.43003329,2541096.37646016
,692899.734,241.9740,-0.019,1.791157e+04,0.5,765360.9,1350032,4.98091396542135E-12,-2.82378254396744E-12,0.0229161318527144,0.0129916263461252,33.0236246155729,18.7217718224731,0.566920561882978,1303772.57951208,2299744.73880735
,693010.323,239.9814,-0.019,5.433485e+04,0.5,142756.2,611342.6,4.54358418881801E-12,-1.06098415712522E-12,0.0314794800713753,0.00735085523725203,30.1241137073295,7.0343601136683,0.233512599972585,243181.509684311,1041406.37255917
,693120.944,237.9770,-0.019,1.648255e+05,0.5,21793.37,221795.8,4.31190860876763E-12,-4.23682593254958E-13,0.0346451024960114,0.00340418320537855,28.588096935851,2.80902963049285,0.0982587136456146,37124.4444564143,377823.432436836
,693235.464,235.9788,-0.019,5.000000e+05,0.5,3184.143,75492.19,4.2089732969891E-12,-1.77527938463499E-13,0.035771421470417,0.00150878284594841,27.9056324083647,1.17701611376843,0.0421784425647209,5424.10558554186,128599.001189264
,693302.076,235.9788,-0.019,2.298591e+01,0.5,9150828,649712.2,5.34536463272956E-11,-7.52864304401108E-10,1.41528669079991E-05,0.000199335106808817,354.399446146001,4991.51528165443,14.0844330766761,15588199.797287,1106767.99786149
,693415.832,233.9901,-0.019,6.972812e+01,0.5,9552864,1666797,4.04581935239334E-11,-2.31876839483042E-10,0.000110141694168652,0.000631251811182001,268.239163501704,1537.3511281851,5.73127021466921,16273057.7679211,2839345.75729307
,693528.496,231.9735,-0.019,2.115173e+02,0.5,9082838,1984016,1.72714516576842E-11,-7.90688166988458E-11,0.000397703903754634,0.00182069102757787,114.510296718432,524.228874376742,4.57800642736752,15472380.5835265,3379720.15308496
,693642.174,229.9822,-0.019,6.416440e+02,0.5,9156166,2738058,7.43604564794399E-12,-2.48664083580964E-11,0.00166495679697856,0.00556767636622892,49.3012290127349,164.865111273982,3.34403653976651,15597292.9427945,4664211.27799146
,693752.717,227.9746,-0.019,1.946446e+03,0.5,6817290,5104000,5.75431621896477E-12,-7.68590172734842E-12,0.00941491996308822,0.0125752820758546,38.1513071804926,50.9577830972768,1.33567594043887,11613077.9199485,8694532.53469007
,693864.273,225.9768,-0.019,5.904585e+03,0.5,2204427,4186200,5.04103200136653E-12,-2.65457623899393E-12,0.0234245675265018,0.0123352322198519,33.4222091856863,17.599928414451,0.526593808227032,3755184.61439052,7131083.87474913
,693973.006,223.9828,-0.019,1.791157e+04,0.5,416245.7,1856142,4.55792148081409E-12,-1.02212827322829E-12,0.0315071011719433,0.00706556684902683,30.2191704282786,6.77674431608042,0.22425315520041,709063.828580494,3161890.08777521
,694084.609,221.9759,-0.019,5.433485e+04,0.5,65321.72,673082.1,4.3112393397655E-12,-4.18400027285152E-13,0.0346585933212399,0.00336357025171804,28.5836596601931,2.77400604309404,0.0970486661285451,111273.867508212,1146578.02056574
,694198.879,219.9811,-0.019,1.648255e+05,0.5,9893.182,229951.8,4.19136839401578E-12,-1.80324617380885E-13,0.0359190917057145,0.00154534172604574,27.7889113183759,1.19555818764868,0.0430228508757053,16852.7807152449,391716.968360216
,694316.099,217.9734,-0.019,5.000000e+05,0.5,1545.233,76923.51,4.13633611101556E-12,-8.30903719530337E-14,0.0364496419721541,0.00073219734270521,27.4240454587859,0.550891918951906,0.0200879159050335,2632.26461445469,131037.217942311
,694382.508,217.9734,-0.019,2.298591e+01,0.5,33475650,6121193,3.65978318098346E-11,-2.00146639458173E-10,0.000133339700019756,0.000729209670233619,242.644837437905,1326.97885075314,5.46881139019796,57024907.5323075,10427294.6100347
,694492.66,215.9826,-0.019,6.972812e+01,0.5,32291910,7201856,1.50172595572134E-11,-6.73348639667573E-11,0.000475897557410214,0.00213384453856207,99.5649284076901,446.432379000298,4.48383166783674,55008436.9322656,12268176.1955629
,694606.494,213.9762,-0.019,2.115173e+02,0.5,32263350,11331020,7.29133106256815E-12,-2.07609523271081E-11,0.00227134805743594,0.00646731691841299,48.3417665170911,137.645801768878,2.84734737031618,54959785.7078944,19302100.7134059
,694717.474,211.9830,-0.019,6.416440e+02,0.5,21122680,18876510,5.83453056575073E-12,-6.52879807181368E-12,0.0114784177792194,0.0128442675927256,38.6831309573,43.2861475245764,1.11899286467679,35981941.3165845,32155648.5768814
,694826.955,209.9758,-0.019,1.946446e+03,0.5,6182831,13329940,5.04805780021276E-12,-2.34144251639147E-12,0.0245886203394922,0.0114049488656545,33.4687904648116,15.523841459027,0.463830369829122,10532293.3554056,22707209.4466039
,694936.951,207.9828,-0.019,5.904585e+03,0.5,1158928,5689388,4.54894313331576E-12,-9.26619447927856E-13,0.031835902104646,0.00648497138081164,30.1596436868992,6.14351763999409,0.203699941012988,1974203.99713231,9691725.91466992
,695046.698,205.9765,-0.019,1.791157e+04,0.5,184849,2049226,4.30108196883696E-12,-3.8797609480728E-13,0.0347846074848674,0.00313772122204688,28.5163159544086,2.5722943627772,0.0902043015265276,314885.510287015,3490803.70845078
,695161.905,203.9855,-0.019,5.433485e+04,0.5,29441.19,699960.9,4.17734148303787E-12,-1.75703963317093E-13,0.0360426464674504,0.00151599668317335,27.6959124338606,1.16492309811684,0.0420611922751685,50152.3088391442,1192365.36404015
,695279.218,201.9780,-0.019,1.648255e+05,0.5,4785.251,234507.8,4.11583238804443E-12,-8.3985654424808E-14,0.0366307512004922,0.000747469119632296,27.2881050961695,0.556827671401763,0.0204055088999172,8151.55182330686,399477.997009912
,695395.579,199.9827,-0.019,5.000000e+05,0.5,792.5955,77896.69,4.08588522888321E-12,-4.15737080218595E-14,0.0369107761894365,0.000375565574214443,27.0895544387383,0.275635061581551,0.0101749573698189,1350.16601912205,132695.005005812
,695457.807,199.9827,-0.019,2.298591e+01,0.5,124949200,29791620,1.25018764647645E-11,-5.24341899759447E-11,0.000648959389763165,0.0027218042047863,82.8878551665014,347.640416760492,4.1941055907668,212847743.844729,50749257.3180101
,695567.554,197.9906,-0.019,6.972812e+01,0.5,118859700,52955440,7.13871375014755E-12,-1.60230067907738E-11,0.00349928748194676,0.00785423103495971,47.3299086793119,106.233065888045,2.24452294230772,202474437.443868,90208228.050319
,695679.579,195.9845,-0.019,2.115173e+02,0.5,64204030,71848380,5.82284495012387E-12,-5.20331998944306E-12,0.0144022937337432,0.0128699533510716,38.6056549385327,34.4981839234677,0.893604420865161,109369911.3819,122391864.709008
,695790.495,193.9696,-0.019,6.416440e+02,0.5,16760050,43098960,4.99916918197572E-12,-1.94404517993873E-12,0.0262075918021851,0.0101914419509012,33.14465730615,12.8890839520011,0.388873652635702,28550313.4811976,73417968.2467292
,695899.15,191.9764,-0.019,1.946446e+03,0.5,3085634,17568310,4.51495744031163E-12,-7.929906852952E-13,0.0324067853716149,0.00569180978553757,29.9343174162869,5.25755451642686,0.175636358875726,5256298.0413687,29927163.5725942
,696010.129,189.9710,-0.019,5.904585e+03,0.5,496210.7,6256460,4.28134979802271E-12,-3.39561282294094E-13,0.0350090463300505,0.00277662821879574,28.3854910081549,2.25130255176254,0.0793117353903006,845282.146397205,10657718.4604207
,696125.539,187.9775,-0.019,1.791157e+04,0.5,80261.39,2130173,4.16539377643555E-12,-1.56945137504825E-13,0.0361586431559342,0.00136239777718019,27.6166987432426,1.04055146147468,0.0376783434960447,136723.210547502,3628694.83797381
,696242.851,185.9684,-0.019,5.433485e+04,0.5,14301.07,714063.4,4.10044009822486E-12,-8.21225130366864E-14,0.0367688176318786,0.000736396004571485,27.1860537046971,0.544474982269968,0.0200277314311306,24361.5043879075,1216388.60954769
,696359.181,183.9790,-0.019,1.648255e+05,0.5,2560.812,237497.2,4.06524557600978E-12,-4.3833483737883E-14,0.0370977035476583,0.000400005744982619,26.9527128563661,0.2906174494484,0.0107824934357121,4362.27728237162,404570.36291101
,696475.652,181.9840,-0.019,5.000000e+05,0.5,390.4037,78602.12,4.04953497246829E-12,-2.01133689082562E-14,0.0372450390297101,0.000184989934671523,26.8485510343712,0.133352302246521,0.00496683422788088,665.042647200898,133896.686840833
,696529.612,181.9840,-0.019,2.298591e+01,0.5,444414100,271466000,6.93091179639156E-12,-1.13465219518199E-11,0.00591342161659713,0.00968079960533016,45.9521748411327,75.2278164671252,1.63708935925678,757047972.438285,462435338.7661
,696642.151,179.9774,-0.019,6.972812e+01,0.5,186489200,274135700,5.69206883716273E-12,-3.87220403540074E-12,0.0181148456771337,0.0123231781867598,37.7386049768,25.6728410463849,0.680280605554111,317679548.739875,466983103.95181
,696750.728,177.9835,-0.019,2.115173e+02,0.5,43627800,140141800,4.89473212764248E-12,-1.52378800841976E-12,0.0280919815864394,0.00874536615240321,32.452236175771,10.102764981107,0.311311828448043,74318833.5652334,238727946.624222
,696860.74,175.9801,-0.019,6.416440e+02,0.5,7818256,54538970,4.45638677196794E-12,-6.38830777667034E-13,0.0331640267670407,0.00475412079207907,29.545991944638,4.23546922131309,0.143351735465485,13318197.718757,92905730.6178459
,696972.562,173.9700,-0.019,1.946446e+03,0.5,1265138,19154460,4.25028380625601E-12,-2.80728120452318E-13,0.0353326230086549,0.00233369377199481,28.1795224534808,1.86123673952447,0.0660492647665348,2155129.99644842,32629129.2426371
,697089.391,171.9715,-0.019,5.904585e+03,0.5,212123.3,6492284,4.14736068917717E-12,-1.35507293839662E-13,0.0363286381346394,0.00118697065711012,27.4971387772575,0.898417847708113,0.0326731393759115,361346.577824417,11059438.5702288
,697205.19,169.9867,-0.019,1.791157e+04,0.5,38404.78,2172113,4.08948756914573E-12,-7.23055708454286E-14,0.0368705541105655,0.000651902326948167,27.1134380740295,0.479388330292543,0.0176808388882162,65421.5535261784,3700138.54771224
,697323.049,167.9712,-0.019,5.433485e+04,0.5,8082.435,722979.2,4.05099151548108E-12,-4.52874378812383E-14,0.0372279133147582,0.000416183742979283,26.8582079628034,0.300257213590433,0.0111793465150865,13768.2198407166,1231576.44520067
,697438.802,165.9875,-0.019,1.648255e+05,0.5,1446.103,239666.5,4.02877138780997E-12,-2.43088558068239E-14,0.0374365540617104,0.000225885191039639,26.7108877801592,0.161168519386529,0.00603381365355609,2463.39921277683,408265.709585677
,697555.943,163.9798,-0.019,5.000000e+05,0.5,127.6387,79108.69,4.02369268843685E-12,-6.49206685070357E-15,0.0374850735150558,6.04806634121504E-05,26.6772158350508,0.0430426183116583,0.00161345991192624,217.429237820444,134759.615787953
,697603.679,163.9798,-0.019,2.298591e+01,0.5,506190700,1015714000,5.46070684582236E-12,-2.72139501944604E-12,0.0221255889278228,0.0110264969738399,36.2046673088585,18.0429391426506,0.49835947914472,862282819.339252,1730242636.93969
,697712.74,161.9798,-0.019,6.972812e+01,0.5,107926700,455441000,4.74520744684694E-12,-1.12448062548961E-12,0.0300954725343669,0.00713178004521958,31.4608825881293,7.45534380265337,0.236971858045279,183850353.548537,775832012.565004
,697823.11,159.9707,-0.019,2.115173e+02,0.5,18716440,169606200,4.38299682029305E-12,-4.83673928236147E-13,0.0339982378372902,0.00375178489104391,29.059414133519,3.20677416901717,0.110352333817985,31882973.454854,288919793.100539
,697935.431,157.9817,-0.019,6.416440e+02,0.5,3047073,58632140,4.21907129387695E-12,-2.19262306043196E-13,0.035652999320832,0.00185286246757368,27.9725824622923,1.45371635354132,0.0519693294496841,5190610.37109633,99878340.2837976
,698052.541,155.9740,-0.019,1.946446e+03,0.5,519180.4,19805650,4.1256359896926E-12,-1.08148399238752E-13,0.0365338184888202,0.000957688462461624,27.3531032999043,0.717027470064634,0.0262137521363853,884410.438709523,33738414.6347344
,698168.793,153.9805,-0.019,5.904585e+03,0.5,101163.4,6609558,4.07716745052789E-12,-6.24035860892262E-14,0.036984864003471,0.000566076368666216,27.03175527941,0.413737843291952,0.0153056225544885,172329.246202952,11259211.808566
,698286.074,151.9742,-0.019,1.791157e+04,0.5,21346.35,2197668,4.04281618074819E-12,-3.92686107182314E-14,0.0373043377168031,0.000362343834201107,26.8040052226637,0.260352190087314,0.00971318233691349,36362.957400447,3743670.83198418
,698402.56,149.9787,-0.019,5.433485e+04,0.5,5148.297,729404.1,4.01561044045926E-12,-2.83430750989542E-14,0.0375587466502898,0.000265098020018598,26.6236302631829,0.187915526952828,0.00705822328116883,8769.99133321851,1242521.09686253
,698519.873,147.9735,-0.019,1.648255e+05,0.5,712.1965,241248.8,4.00245835745571E-12,-1.18157554921546E-14,0.03768371359169,0.000111247015226621,26.536431517122,0.078338850385925,0.00295212452870232,1213.20839348401,410961.116879886
,698636.109,145.9811,-0.019,5.000000e+05,0.5,-47.00503,79450.53,4.00638957057223E-12,2.37028578609148E-15,0.0376470518960704,-2.2272989290145E-05,26.5624955903312,-0.015715073292757,-0.000591626386885021,-80.0718578818736,135341.931423074
,698673.612,145.9811,-0.019,2.298591e+01,0.5,250557600,1469504000,4.57872333918424E-12,-7.80694663593968E-13,0.0320106264477907,0.00545796795194498,30.3570874384682,5.17603148516284,0.170504877836331,426818417.910239,2503262213.53002
,698783.671,143.9883,-0.019,6.972812e+01,0.5,42263260,526802300,4.3050811290233E-12,-3.45379591313487E-13,0.0348110164668778,0.00279274984145653,28.5428305189419,2.28987813333005,0.0802260354596022,71994374.8221131,897394149.039882
,698898.893,141.9746,-0.019,2.115173e+02,0.5,6990079,179755600,4.17956380474505E-12,-1.62528906919776E-13,0.0360327254627767,0.00140118915666672,27.710646500408,1.0775720376941,0.0388865715449199,11907419.5308687,306209034.579297
,699016.253,139.9669,-0.019,6.416440e+02,0.5,1227280,60333860,4.10944527653146E-12,-8.35921984600609E-14,0.0366877802789251,0.000746283744827849,27.2457583352244,0.554219045319729,0.020341479892054,2090639.86856866,102777176.472068
,699132.442,137.9735,-0.019,1.946446e+03,0.5,244569.6,20130640,4.06122129438856E-12,-4.93402727126456E-14,0.0371333002362348,0.000451136992438186,26.9260317358872,0.327127642798899,0.0121491219355172,416618.014145011,34292026.7288662
,699248.881,135.9809,-0.019,5.904585e+03,0.5,56048.96,6682257,4.03347124622374E-12,-3.383166324503E-14,0.0373916631613252,0.000313631132843677,26.7420479971555,0.224305048206115,0.00838772887663554,95477.9596895655,11383052.6825354
,699366.116,133.9735,-0.019,1.791157e+04,0.5,14145.5,2215764,4.01001364154717E-12,-2.56000404224031E-14,0.0376115084520202,0.000240112932969419,26.5865233009658,0.169729116166618,0.00638402826293775,24096.4948999723,3774496.9018799
,699482.462,131.9819,-0.019,5.433485e+04,0.5,3205.175,734061.3,3.99025639197649E-12,-1.74228910189833E-14,0.0377985569213038,0.000165042060765552,26.4555320817261,0.115514344701248,0.00436635877684875,5459.93305581412,1250454.51710558
,699599.681,129.9763,-0.019,1.648255e+05,0.5,214.7383,242249.9,3.98594976590662E-12,-3.53327731658996E-15,0.0378400881132488,3.35427019507098E-05,26.4269790081982,0.0234257456715407,0.000886432976855718,365.801162969051,412666.464944243
,699715.558,127.9892,-0.019,5.000000e+05,0.5,-148.3072,79676.16,3.99503167991725E-12,7.4362514754705E-15,0.0377539650194858,-7.02742808004036E-05,26.4871923989855,-0.049302593656055,-0.00186137484537407,-252.637495205483,135726.286316452
,699744.387,127.9892,-0.019,2.298591e+01,0.5,89623890,1628687000,4.23848025425347E-12,-2.33236397217136E-13,0.0354781553213689,0.00195230286109319,28.1012645126354,1.54636504100624,0.055028308078839,152671988.144687,2774426353.90415
,699862.106,125.9756,-0.019,6.972812e+01,0.5,15319530,550615100,4.1422002102778E-12,-1.15246676648274E-13,0.0363845626965022,0.00101231223002411,27.4629246311806,0.764089284465882,0.0278225751527701,26096424.7651177,937958640.486212
,699978.592,123.9827,-0.019,2.115173e+02,0.5,2834756,184036900,4.08753684691897E-12,-6.29611213948107E-14,0.0368909290877196,0.000568238122773138,27.1005047210359,0.417434320839923,0.015403193598675,4828933.83031111,313502118.854526
,700095.764,121.9736,-0.019,6.416440e+02,0.5,590739,61184530,4.05360908760089E-12,-3.9137752284773E-14,0.0372050552228765,0.000359216244977396,26.8755625526816,0.259484594337958,0.00965503861842201,1006308.67065248,104226270.906097
,700211.423,119.9832,-0.019,1.946446e+03,0.5,141554.9,20321750,4.02342730135767E-12,-2.80259253903308E-14,0.0374858247962163,0.000261114430619701,26.6754563099232,0.18581281387703,0.00696568454980501,241135.126076567,34617577.6913867
,700328.845,117.9735,-0.019,5.904585e+03,0.5,39607.73,6732652,4.00342314782551E-12,-2.35518638294126E-14,0.037673656635239,0.000221631538377634,26.5428281092386,0.156149637496061,0.00588293142137749,67470.7478664224,11468899.2669957
,700445.191,115.9815,-0.019,1.791157e+04,0.5,9158.688,2228933,3.98641680605215E-12,-1.63801907749529E-14,0.0378350457758529,0.000155464242185276,26.4300754998367,0.108601207537171,0.0041090010332298,15601.5891048345,3796929.95418189
,700562.457,113.9754,-0.019,5.433485e+04,0.5,1727.479,736947.4,3.97468332586496E-12,-9.31705841839169E-15,0.0379471690537382,8.89519898567831E-05,26.3522821374486,0.0617724060014562,0.00234410081370801,2942.71598128798,1255370.91411741
,700678.74,111.9835,-0.019,1.648255e+05,0.5,-101.3488,242931.2,3.97477361024482E-12,1.65824124554598E-15,0.0379465090117984,-1.58309560588963E-05,26.3528807258784,-0.0109941943978826,-0.000417191369408293,-172.645070327546,413827.041945788
,700795.007,109.9909,-0.019,5.000000e+05,0.5,-201.898,79847.04,3.98647026923427E-12,1.00800276931726E-14,0.037834935256286,-9.56678889834067E-05,26.4304299625055,-0.0668309175715209,-0.00252855960596661,-343.928042650638,136017.375995043
,700823.852,109.9909,-0.019,2.298591e+01,0.5,32403830,1685134000,4.10738963527701E-12,-7.89819417834299E-14,0.0367077564868631,0.000705861908240953,27.2321293656011,0.523652890809244,0.0192292304350871,55199089.7695075,2870582364.48127
,700941.742,107.9748,-0.019,6.972812e+01,0.5,6414822,560954500,4.06846733086141E-12,-4.6525152646589E-14,0.0370677886878421,0.000423890469487491,26.9740731977738,0.308463303491976,0.0114355478028967,10927484.0484415,955571542.071082
,701058.493,105.9757,-0.019,2.115173e+02,0.5,1417226,186181800,4.04117101242171E-12,-3.07616138057015E-14,0.0373208828296064,0.000284088592381596,26.7930977021523,0.203950518708223,0.00761205445430219,2414207.98707066,317155900.757672
,701174.807,103.9827,-0.019,6.416440e+02,0.5,352163.8,61676160,4.02154090739152E-12,-2.29625373532082E-14,0.0375040053218512,0.000214143569076988,26.6629494554286,0.152242383433594,0.00570988531062894,599901.962507854,105063749.948031
,701290.997,101.9925,-0.019,1.946446e+03,0.5,99529.72,20449500,3.9983918464442E-12,-1.94605648513105E-14,0.0377214744876905,0.000183594112019706,26.5094704143863,0.129024189720636,0.00486709797305558,169546.314402154,34835196.5258904
,701407.81,99.9922,-0.019,5.904585e+03,0.5,29327.87,6764542,3.98461286042164E-12,-1.72754057807275E-14,0.0378521023517409,0.000164108898577103,26.4181152805391,0.114536512685214,0.00433552929377924,49959.2711379625,11523223.0605951
,701525.076,97.9816,-0.019,1.791157e+04,0.5,5779.492,2237313,3.9715259768856E-12,-1.02593613907408E-14,0.0379772921706981,9.81040454698169E-05,26.3313488091079,0.0680199059279809,0.00258322907881016,9845.21575783327,3811205.06833563
,701641.328,95.9976,-0.019,5.433485e+04,0.5,919.9622,738693.1,3.96530588242793E-12,-4.93835873554436E-15,0.0380370592860901,4.73710350649842E-05,26.290109376773,0.0327414820315726,0.00124539162474917,1567.13191194848,1258344.66910287
,701759.125,93.9810,-0.019,1.648255e+05,0.5,-261.651,243333.7,3.96819501156422E-12,4.26690669221234E-15,0.038009380597981,-4.08705922888705E-05,26.3092643986675,-0.0282897327381113,-0.00107527646191218,-445.715739074097,414512.69032847
,701875.345,91.9867,-0.019,5.000000e+05,0.5,-227.7239,79954.73,3.98109410249052E-12,1.13387947815738E-14,0.0378859633742695,-0.000107905302598681,26.3947857988743,-0.0751765850723812,-0.00284816045279623,-387.921798094927,136200.823136238
,701904.174,91.9867,-0.019,2.298591e+01,0.5,14368510,1709885000,4.04914502625825E-12,-3.40257858284281E-14,0.0372469146077048,0.000312993367980859,26.8459656780791,0.225592087365604,0.00840320255455776,24476386.6908346,2912745055.46209
,702021.487,89.9818,-0.019,6.972812e+01,0.5,3297508,566437200,4.02947785990327E-12,-2.34575615423103E-14,0.0374300846762669,0.000217898830904233,26.7155717135442,0.155524410208202,0.00582148912536112,5617219.94306442,964911180.301478
,702138.8,87.9752,-0.019,2.115173e+02,0.5,850211.1,187464700,4.01366557421908E-12,-1.82032298501475E-14,0.037578045240659,0.000170428198908437,26.6107357355743,0.120688017005612,0.00453531304826989,1448312.70969918,319341287.863619
,702254.459,85.9912,-0.019,6.416440e+02,0.5,258714.7,62015430,3.99960090985808E-12,-1.66854531124538E-14,0.0377103084361428,0.00015731909194154,26.5174865448783,0.110625106948581,0.00417177950713234,440713.827655286,105641687.654348
,702371.897,83.9760,-0.019,1.946446e+03,0.5,75551.48,20542940,3.98024552591914E-12,-1.46382864500685E-14,0.0378938354048831,0.000139363467337943,26.3891597080915,0.0970523241513961,0.00367773454043092,128700.000177113,34994369.1591274
,702489.116,81.9690,-0.019,5.904585e+03,0.5,18743.53,6788238,3.97074796080818E-12,-1.09639399098628E-14,0.0379846971996,0.000104882491082608,26.3261905367379,0.0726912848534572,0.0027611774955445,31929.1205720884,11563588.5862499
,702605.898,79.9774,-0.019,1.791157e+04,0.5,3427.423,2242817,3.96179681225537E-12,-6.0543296736429E-15,0.0380707198744247,5.81788264152448E-05,26.2668441252683,0.040140406324885,0.00152817773362695,5838.5267993035,3820580.99056739
,702722.68,77.9748,-0.019,5.433485e+04,0.5,406.7451,740126.1,3.95763337245659E-12,-2.17496448489412E-15,0.0381108478539771,2.09442696608736E-05,26.2392403814617,0.0144200865945434,0.000549561892223501,692.879801190393,1260785.74769265
,702839.198,75.9837,-0.019,1.648255e+05,0.5,-344.2334,243697.5,3.96226782914834E-12,5.59687697468522E-15,0.0380662071397282,-5.37701860249404E-05,26.2699669828742,-0.0371074797747311,-0.00141254382995312,-586.392730373625,415132.414257961
,702955.34,73.9912,-0.019,5.000000e+05,0.5,-241.2266,80061.03,3.97580441413254E-12,1.19792336057403E-14,0.0379363328509306,-0.000114303458125611,26.3597149898059,-0.0794227156952629,-0.00301303393173932,-410.923299751698,136381.902448236
,702984.185,73.9912,-0.019,2.298591e+01,0.5,7770436,1723506000,4.01734632961181E-12,-1.81122273691437E-14,0.0375436247512943,0.000169265632575661,26.6351392657768,0.120084667541514,0.00450850533737625,13236737.5804716,2935948078.12178
,703101.997,71.9774,-0.019,6.972812e+01,0.5,2098226,569713500,4.00638662753806E-12,-1.47553192753071E-14,0.0376465820857323,0.000138650457367462,26.5624760779172,0.0978282556601938,0.00368294941229232,3574273.9463426,970492272.962804
,703218.857,69.9734,-0.019,2.115173e+02,0.5,628320.5,188334800,3.99516029284251E-12,-1.33286100751372E-14,0.0377524602487319,0.00012594934499473,26.4880451069411,0.0883691263941438,0.00333618906330641,1070327.78790414,320823480.802184
,703334.969,67.9834,-0.019,6.416440e+02,0.5,201293.6,62260760,3.98386872141585E-12,-1.28801395431279E-14,0.0378594885670979,0.000122402501155302,26.4131816142764,0.0853957519084493,0.00323307328725187,342898.462818356,106059600.990308
,703451.47,65.9906,-0.019,1.946446e+03,0.5,58735.25,20610990,3.9671256430787E-12,-1.13051394633464E-14,0.0380193615223377,0.000108343980752738,26.3021744501788,0.0749534491974847,0.00284970542414508,100053.985512961,35110290.5813424
,703569.298,63.9740,-0.019,5.904585e+03,0.5,12162.46,6805522,3.96068098952615E-12,-7.07831436117202E-15,0.0380814126515918,6.80570363476129E-05,26.2594461836048,0.0469294587292857,0.00178714579131476,20718.4373377482,11593031.4350605
,703686.049,61.9725,-0.019,1.791157e+04,0.5,1939.028,2246641,3.95505974158527E-12,-3.41352783137431E-15,0.0381356304011416,3.2914050418142E-05,26.2221771235168,0.0226318026170886,0.000863078702827911,3303.08425385482,3827095.07607144
,703802.831,59.9788,-0.019,5.433485e+04,0.5,221.9406,741088.2,3.95249630898618E-12,-1.1836909592059E-15,0.0381603886642799,1.14282477529442E-05,26.2051814804546,0.00784791027691572,0.000299479333229162,378.070095507178,1262424.66026154
,703919.271,57.9849,-0.019,1.648255e+05,0.5,-385.0892,243986.7,3.95756934922403E-12,6.24631266637568E-15,0.0381113809601605,-6.01519722380091E-05,26.2388159053087,-0.0414132599273755,-0.0015783204576315,-655.989533338121,415625.059008947
,704036.068,55.9795,-0.019,5.000000e+05,0.5,-248.1098,80144.95,3.97163933111692E-12,1.22952555353213E-14,0.0379760977284603,-0.000117565012046158,26.3321003514172,-0.0815179515586453,-0.0030957633637553,-422.648653658982,136524.858006683
,704064.913,55.9795,-0.019,2.298591e+01,0.5,4830240,1731978000,3.9977455776173E-12,-1.11491431177707E-14,0.0377281727533859,0.000105218501135877,26.5051856306522,0.0739191882579347,0.00278885759518885,8228189.42601124,2950379911.90585
,704181.539,53.9821,-0.019,6.972812e+01,0.5,1577107,571922000,3.99093958875809E-12,-1.10052398089381E-14,0.0377925194323747,0.00010421499250673,26.4600616990234,0.0729651045526518,0.00275755610030738,2686561.15246619,974254395.827785
,704299.414,51.9681,-0.019,2.115173e+02,0.5,528106.1,188968100,3.98178429420292E-12,-1.11278283194505E-14,0.0378794077543205,0.000105860969652782,26.3993617927946,0.0737778704388823,0.00279468386463112,899615.138757502,321902291.04008
,704416.212,49.9636,-0.019,6.416440e+02,0.5,162224.4,62438800,3.97252369812894E-12,-1.03211508455439E-14,0.0379677510320034,9.86453235891165E-05,26.3379637340072,0.068429572060499,0.00259813449329584,276345.08693585,106362887.544476
,704531.559,47.9910,-0.019,1.946446e+03,0.5,42264.92,20658550,3.95800812368537E-12,-8.09761075713989E-15,0.0381070914583574,7.79625468350953E-05,26.2417249945246,0.0536874276053054,0.00204588027717337,71997.202589356,35191307.8163248
,704769.351,43.9718,-0.019,5.904585e+03,0.5,7359.692,6818115,3.95337366591498E-12,-4.26739832667022E-15,0.0381518788450038,4.11823616234903E-05,26.2109983859606,0.0282929922908557,0.00107943207176764,12537.0457561321,11614483.2861987
,704885.712,41.9819,-0.019,1.791157e+04,0.5,1103.644,2249422,3.95017202323924E-12,-1.93809060834999E-15,0.0381828365137985,1.87338162521015E-05,26.1897713889454,0.0128496049450843,0.000490634482991631,1880.02912709943,3831832.43794036
,705002.697,39.9805,-0.019,5.433485e+04,0.5,39.3404,741789.3,3.94876096164181E-12,-2.09420432102989E-16,0.0381964899657074,2.02573047878544E-06,26.180416003804,0.00138846440324234,5.30344667953555E-05,67.0153580971241,1263618.96605309
,705119.386,37.9830,-0.019,1.648255e+05,0.5,-402.0179,244201.7,3.95408416084149E-12,6.50942483514553E-15,0.0381449645403575,-6.2796280861636E-05,26.2157089908631,-0.0431577023236034,-0.00164625348635984,-684.827137750349,415991.305971125
,705236.605,35.9709,-0.019,5.000000e+05,0.5,-249.594,80198.56,3.96898402078893E-12,1.23522741266775E-14,0.0380015004344227,-0.000118268289348703,26.3144955559684,-0.0818959867084443,-0.00311220051831355,-425.176950129983,136616.181260833
,705265.434,35.9709,-0.019,2.298591e+01,0.5,3397472,1737729000,3.98453083071847E-12,-7.79024343295344E-15,0.037853448433276,7.40081054960233E-05,26.4175714208894,0.0516495720624285,0.00195512188609386,5787506.04226069,2960176592.27556
,705382.373,33.9722,-0.019,6.972812e+01,0.5,1281636,573580500,3.97941023428901E-12,-8.89178661937293E-15,0.0379021128620357,8.46903134260108E-05,26.3836216969094,0.0589528398840967,0.00223444834683187,2183233.91450432,977079607.859286
,705498.547,31.9797,-0.019,2.115173e+02,0.5,440211.2,189470300,3.97123996566079E-12,-9.2266931058403E-15,0.0379800757431198,8.8242087118507E-05,26.3294525452115,0.061173280985308,0.00232337838700841,749888.440543683,322757775.804759
,705615.469,29.9790,-0.019,6.416440e+02,0.5,120430.2,62569570,3.96423322276659E-12,-7.6301211573681E-15,0.0380472695814062,7.32311295273832E-05,26.2829976076795,0.0505879560702169,0.00192474073259573,205149.743742013,106585650.871193
,705732.252,27.9802,-0.019,1.946446e+03,0.5,28704.18,20688320,3.95232157873916E-12,-5.48368113089962E-15,0.0381620056760888,5.29481891273663E-05,26.2040230131278,0.0363569875800917,0.00138745823730491,48896.8312875392,35242020.2445296
,705848.535,25.9865,-0.019,5.904585e+03,0.5,6891.378,6824746,3.94953309844162E-12,-3.98809355027608E-15,0.0381889836912291,3.85618339572044E-05,26.1855352963688,0.0264411923695943,0.00100976329375482,11739.2849196409,11625779.023902
,705965.473,23.9870,-0.019,1.791157e+04,0.5,707.7985,2250554,3.94818569691966E-12,-1.24170311576669E-15,0.0382020516592597,1.20145328045213E-05,26.1766019796368,0.00823253279693975,0.000314499674302416,1205.71651376466,3833760.77078309
,706083.098,21.9710,-0.019,5.433485e+04,0.5,-83.83868,742064.9,3.94729436799E-12,4.45966315592768E-16,0.0382106812632019,-4.3170524289824E-06,26.1706924393022,-0.00295677144788424,-0.000112980252805381,-142.817031921134,1264088.44355438
,706199.771,19.9745,-0.019,1.648255e+05,0.5,-406.9806,244278.4,3.95284237450883E-12,6.58564228881075E-15,0.0381569452873394,-6.35714679939305E-05,26.2074759063354,-0.0436630265665975,-0.0016660523402806,-693.280969374547,416121.96244554
,706296.024,20.0075,-0.019,5.000000e+05,0.5,-251.3223,80230.26,3.96741532129721E-12,1.24279784660258E-14,0.0380165212473123,-0.000119087231648924,26.304095026365,-0.0823979089865172,-0.00313251259562165,-428.121064663624,136670.181394327
,706324.853,20.0075,-0.019,2.298591e+01,0.5,3152720,1741204000,3.97658088472136E-12,-7.2002166816058E-15,0.0379291453533974,6.86766025914041E-05,26.3648630155354,0.0477376751525604,0.00181065515585767,5370577.31441381,2966096165.2689
,706443.663,18.9881,-0.019,6.972812e+01,0.5,1187112,574586900,3.97244309796705E-12,-8.20717435589613E-15,0.0379686156221267,7.84441817737474E-05,26.3374293522635,0.0544138378950585,0.00206602691429269,2022214.71518828,978793984.33713
,706559.853,17.9929,-0.019,2.115173e+02,0.5,372346.1,189704700,3.96633921376377E-12,-7.78499919887071E-15,0.038027062156052,7.46382577145614E-05,26.2969603977653,0.051614802616711,0.00196276686871754,634281.990716098,323157070.167245
,706677.727,16.9858,-0.019,6.416440e+02,0.5,102776.4,62626240,3.96065002455439E-12,-6.49985295594326E-15,0.0380817294437191,6.24962165699147E-05,26.2592408848161,0.0430942404473623,0.00164110762517437,175076.950156411,106682186.756526
,706793.995,15.9907,-0.019,1.946446e+03,0.5,23425.04,20698920,3.95030012412178E-12,-4.47056843639947E-15,0.0381815586054792,4.32102031215008E-05,26.1906207020409,0.0296400168496779,0.00113170348984391,39903.9522739844,35260077.0715022
,706910.231,14.9937,-0.019,5.904585e+03,0.5,3791.602,6824876,3.94946067585464E-12,-2.19414726326043E-15,0.0381897111275146,2.12165298080883E-05,26.1850551322176,0.014547269050665,0.000555556174207414,6458.89634553212,11626000.4755536
,707027.091,13.9934,-0.019,1.791157e+04,0.5,446.3296,2250907,3.94756675529143E-12,-7.82758190748229E-16,0.0382080436613337,7.5762263141683E-06,26.1724983761352,0.00518971273856321,0.000198288778701208,760.310977350158,3834362.09719076
,707144.825,12.9853,-0.019,5.433485e+04,0.5,-90.00037,742207.2,3.94653756359655E-12,4.7855887270103E-16,0.0382180086276194,-4.63433245749831E-06,26.1656748010995,-0.00317286118135021,-0.000121260437786106,-153.313312127575,1264330.84793911
,707261.249,11.9886,-0.019,1.648255e+05,0.5,-414.5808,244314.6,3.9522562731926E-12,6.706637947733E-15,0.0381625998250283,-6.47586397437571E-05,26.2035900351904,-0.0444652317940118,-0.00169691373335855,-706.22771431384,416183.628213125
,707378.936,10.9883,-0.019,5.000000e+05,0.5,-254.0296,80241.94,3.96683699360046E-12,1.25581960599348E-14,0.0380220557297902,-0.000120370065930813,26.3002606945748,-0.0832612559484298,-0.00316579584192506,-432.732880480859,136690.077973481
,707407.78,10.9883,-0.019,2.298591e+01,0.5,2593959,1742884000,3.97275200515801E-12,-5.91270320833037E-15,0.0379657412744921,5.65049517183245E-05,26.3394774171741,0.0392014181675749,0.00148831419646976,4418742.34309407,2968958001.99662
,707520.741,9.9927,-0.019,6.972812e+01,0.5,996426.6,574923700,3.97012099468457E-12,-6.88079855522075E-15,0.0379908713152891,6.58437193243747E-05,26.3220337305661,0.0456199223918466,0.00173314580700013,1697387.04783123,979367714.462068
,707590.005,10.0186,-0.019,2.115173e+02,0.5,336823,189773200,3.96491031961703E-12,-7.03720540405267E-15,0.0380407932536879,6.75175109345625E-05,26.2874867822311,0.0466569049815856,0.00177487126738654,573769.304845594,323273758.152869
,707812.509,8.9998,-0.019,6.416440e+02,0.5,93929.91,62642510,3.95962309517422E-12,-5.93729467359523E-15,0.0380916228963366,5.7116847814796E-05,26.252432309002,0.0393644603970315,0.00149945955230721,160007.182303196,106709902.282455
,708035.014,8.0000,-0.019,1.946446e+03,0.5,22832.87,20702700,3.94957911331662E-12,-4.35596450941537E-15,0.0381885312538845,4.21178768764886E-05,26.1858403765145,0.0288801890167807,0.00110289334241427,38895.2059316906,35266516.2041395
,708257.424,6.9960,-0.019,5.904585e+03,0.5,5748.776,6824274,3.94980749174009E-12,-3.32732221964353E-15,0.0381863425379463,3.21682173825266E-05,26.1873545330286,0.0220602565551979,0.00084240111109255,9792.8918429948,11624974.9840595
,708491.254,5.9996,-0.019,1.791157e+04,0.5,423.8135,2251204,3.94704597046562E-12,-7.43074091643375E-16,0.0382130850908408,7.19402654674879E-06,26.1690455554858,0.00492660584670686,0.000188260815101608,721.955380954324,3834868.02904084
,708718.438,5.0035,-0.019,5.433485e+04,0.5,-54.58821,742323.8,3.94591770060773E-12,2.90170656098447E-16,0.0382240126380979,-2.81087637083863E-06,26.1615650889467,-0.00192384106370305,-7.35369255303413E-05,-92.989609689556,1264529.47303581
,709780.992,3.9988,-0.019,1.648255e+05,0.5,-409.8299,244356.5,3.95157883982658E-12,6.62751005505581E-15,0.0381691447180993,-6.4016536343024E-05,26.1990986295294,-0.0439406112439414,-0.00167718026735528,-698.134678534243,416255.003783894
,710098.314,2.9974,-0.019,5.000000e+05,0.5,-255.4885,80254.23,3.96622907317604E-12,1.26264486814232E-14,0.0380278792563016,-0.000121061355013606,26.2962301620196,-0.0837137730902051,-0.0031834895182472,-435.21807905352,136711.013671924
,710127.159,2.9974,-0.019,2.298591e+01,0.5,2067079,1744106000,3.96997173175966E-12,-4.70512984721916E-15,0.0379923604504312,4.50277737978751E-05,26.3210441124286,0.0311951667747687,0.00118517968517969,3521215.83410553,2971039647.52119
,710354.967,1.9994,-0.019,6.972812e+01,0.5,833876.6,575100500,3.96890405963303E-12,-5.75477890033652E-15,0.0380025542326023,5.51024398601602E-05,26.3139654108555,0.0381543747733166,0.00144996674494284,1420487.30968196,979668888.708175
,710360.63,1.9994,-0.019,1.000008e+01,0.5,6498441,4005595000,3.97330544397823E-12,-6.44605632937712E-15,0.0379604372279575,6.15847737127906E-05,26.3431467348884,0.0427375670308693,0.00162234100052551,11069926.861141,6823427909.14809