File: Scripts/Data_examples/Nb-PrO2/Jan 30 2019 Pr0.998Nb0.002O2 1300C 10h air.dat
Comment,Time Stamp (sec),Temperature (K),Magnetic Field (Oe),Frequency (Hz),AC Voltage (Vrms),Re[Impedance] (Ohm),-Im[Impedance] (Ohm),Re[Cp] (F),Im[Cp] (F),Re[Modulus],Im[Modulus],Re[Permittivity],Im[Permittivity],Loss Factor,Re[Sp.Impedance] (Ohm-cm),-Im[Sp.Impedance] (Ohm-cm)
,580746.232,360.0038,-0.019,5.000000e+05,0.5,5148.282,941.3527,1.09394469309779E-11,-5.98281151418683E-11,0.000474708202152684,0.0025961913025745,68.1507870037873,372.718397703042,5.46902558414078,9333.36151272169,1706.58582029435
,580906.476,360.0013,-0.019,2.175258e+05,0.5,5634.833,883.2887,1.98658606748715E-11,-1.26731845776096E-10,0.000193783951047319,0.00123622118366489,123.760739280726,789.516607427932,6.37937856558111,10215.4337025078,1601.32113143802
,581014.694,357.9240,-0.019,9.463495e+04,0.5,6367.068,725.6397,2.97170763997586E-11,-2.60750130124438E-10,6.92591147083283E-05,0.00060770860933839,185.132041580661,1624.42641675048,8.77442069390636,11542.9083760528,1315.51800155526
,581158.621,355.9880,-0.019,4.117107e+04,0.5,7349.385,509.0272,3.62567134502683E-11,-5.23478010567411E-10,2.11367231656605E-05,0.0003051740971462,225.872804301424,3261.1738623021,14.4380987892199,13323.7587026457,922.819472089618
,581278.975,353.9878,-0.019,1.791157e+04,0.5,8142.095,308.6567,4.13111005035073E-11,-1.08975086189318E-09,5.5758765161371E-06,0.000147086767605101,257.360726650092,6788.95188620263,26.3791293044991,14760.8689861829,559.566194008736
,581401.966,351.9794,-0.019,7.792469e+03,0.5,8961.324,204.3419,5.19437851191329E-11,-2.27797181213901E-09,1.60596336777488E-06,7.04288159734342E-05,323.6004395981,14191.3547137469,43.8545594417983,16246.0557763986,370.453060826199
,581523.242,349.9837,-0.019,3.390107e+03,0.5,9837.104,185.247,8.98396782381862E-11,-4.77072372646021E-09,6.33388479597298E-07,3.36345978407235E-05,559.685038442078,29720.7508375235,53.1026359401232,17833.7643256994,335.835764269936
,581645.016,347.9792,-0.019,1.474880e+03,0.5,10892.61,254.34,2.31195185086074E-10,-9.90138784705678E-09,3.78333163883148E-07,1.62028607542865E-05,1440.30442439322,61683.8655979783,42.8269639065817,19747.2995743216,461.095015219763
,581767.336,345.9736,-0.019,6.416440e+02,0.5,12108.02,443.3891,7.49170619698503E-10,-2.04582675729328E-08,2.86936321724426E-07,7.83562501235547E-06,4667.19822809215,127451.327715779,27.3078882633786,21950.7260603177,803.823636914277
,581889.641,343.9701,-0.019,2.791500e+02,0.5,13618.03,709.0538,2.17399250689311E-09,-4.17535244556133E-08,1.99627547807268E-07,3.83403055574317E-06,13543.582341951,260116.948305134,19.2059192123362,24688.2352367429,1285.44929111674
,582011.494,341.9721,-0.019,1.214445e+02,0.5,15526.89,808.6344,4.38378616992768E-09,-8.41747094162559E-08,9.9045389607666E-08,1.901807379757E-06,27310.1994480981,524393.301482944,19.2013720910216,28148.8227603428,1465.97975534805
,582134.032,339.9730,-0.019,5.283509e+01,0.5,17530.9,597.1002,5.84570559143509E-09,-1.71630289443697E-07,3.18177919377367E-08,9.34172403025939E-07,36417.6945290167,1069225.83683398,29.3600638552792,31781.908478085,1082.48771646899
,582255.885,337.9789,-0.019,2.298591e+01,0.5,19461.58,345.213,6.3089229671408E-09,-3.5566913482067E-07,8.0029615768914E-09,4.51171528782514E-07,39303.4554735466,2215754.74554801,56.3755710242662,35282.0536537731,625.839401938587
,582378.221,335.9748,-0.019,1.000008e+01,0.5,21463.28,183.155,6.32725160316281E-09,-7.41468006820083E-07,1.84723920726587E-09,2.16471362138764E-07,39417.6395796982,4619212.33511585,117.186426796975,38910.9515540853,332.043160779177
,582587.262,331.9855,-0.019,2.870762e+05,0.5,17023.11,3947.211,7.16624324331075E-12,-3.09058084347748E-11,0.00114285697912167,0.00492879151123563,44.6444066115639,192.537628374409,4.31269319020443,30861.3319357463,7155.93031422748
,582710.378,329.9767,-0.019,1.248930e+05,0.5,20205.99,3652.469,1.10393848843416E-11,-6.10714835852563E-11,0.000460075227782796,0.00254520310831574,68.7733824801636,380.464359495005,5.5321455158141,36631.6004819548,6621.59019086543
,582832.293,327.9843,-0.019,5.433485e+04,0.5,24175.61,3750.434,1.83543922134731E-11,-1.18313941250523E-10,0.000205524976533093,0.00132483112032453,114.344562592303,737.074576129619,6.44608330662531,43828.1562510697,6799.19172096689
,582955.58,325.9662,-0.019,2.363846e+04,0.5,28915.1,3347.08,2.65972495410859E-11,-2.29771063197011E-10,7.9797620596266E-05,0.000689363916997231,165.696081328226,1431.43240114183,8.63890316335433,52420.4154854957,6067.94803625763
,583077.417,323.9758,-0.019,1.028394e+04,0.5,33536.73,2384.318,3.2643217951319E-11,-4.59144621969275E-10,2.47302664362761E-05,0.000347844653398352,203.361377202612,2860.38842120563,14.0655441094686,60799.0053855905,4322.54912518187
,583199.519,321.9741,-0.019,4.474074e+03,0.5,37891.07,1493.845,3.69552716306802E-11,-9.37362834984298E-10,6.74079197313417E-06,0.00017097879666864,230.224696135023,5839.60188438619,25.3647935361433,68693.0231121456,2708.20351895481
,583322.885,319.9836,-0.019,1.946446e+03,0.5,42422.98,982.364,4.46082939853892E-11,-1.92639058798601E-09,1.92849534327891E-06,8.3281267817239E-05,277.901649067083,12001.0669164789,43.1845833112777,76908.9589084207,1780.93553326786
,583444.8,317.9865,-0.019,8.467957e+02,0.5,47696.49,861.8215,7.11770988473048E-11,-3.93921221900299E-09,7.3604480010292E-07,4.07355275398223E-05,443.420525159637,24540.583687076,55.3438153956475,86469.3472614583,1562.40307328466
,583568.103,315.9723,-0.019,3.684033e+02,0.5,53428.12,1070.963,1.62015667409971E-10,-8.08262518897483E-09,3.97925857150368E-07,1.98516946401815E-05,1009.32847068041,50353.3013287383,49.8879232989375,96860.2650175487,1941.55736724386
,583690.938,313.9735,-0.019,1.602760e+02,0.5,60173.31,1658.143,4.54402335044397E-10,-1.6490069053966E-08,2.68034343548785E-07,9.72685325994654E-06,2830.84482652782,102730.164592894,36.2895781606291,109088.6737842,3006.06067398578
,583814.46,311.9762,-0.019,6.972812e+01,0.5,68529.23,2297.674,1.11548574804311E-09,-3.32698979008198E-08,1.61583734471195E-07,4.81931244547115E-06,6949.27559869343,207265.480584387,29.8254800289336,124237.187818859,4165.47152630359
,583935.392,309.9838,-0.019,3.033521e+01,0.5,78083.44,2135.939,1.83662550239566E-09,-6.71414479621289E-08,6.53489848889225E-08,2.3889603310933E-06,11441.8465768179,418279.145926063,36.5569615986224,141558.091354924,3872.26085442119
,584060.77,307.9843,-0.019,1.319742e+01,0.5,88365.13,1384.782,2.13819173605521E-09,-1.36441397072929E-07,1.84319879936333E-08,1.17617431134709E-06,13320.5499781268,850005.365818355,63.8115818952008,160197.849187097,2510.48233610936
,584266.223,303.9683,-0.019,3.788642e+05,0.5,40743.49,37667.17,5.13938706580728E-12,-5.55912656888872E-12,0.0143929873875403,0.015568478802479,32.0174571403623,34.6323587576072,1.08167112103192,73864.1980878205,68287.1130157876
,584388.902,301.9777,-0.019,1.648255e+05,0.5,70347.71,34396.07,5.41639392292115E-12,-1.10777454789288E-11,0.00571791303392171,0.0116944199705241,33.7431600426084,69.0123620855814,2.04522522485854,127533.924719374,62356.9097277268
,584510.942,299.9808,-0.019,7.170755e+04,0.5,92673.14,26150.43,6.25969410375902E-12,-2.21834022627863E-11,0.00189124731731562,0.00670229236812607,38.9967685081142,138.198606581232,3.54384765374795,168007.874887014,47408.3231849232
,584635.384,297.9700,-0.019,3.119651e+04,0.5,112161.6,22142.05,8.64251269951801E-12,-4.37790562481007E-11,0.00069667156752015,0.00352902272768637,53.8412998279182,272.735647095866,5.06554722801186,203338.659507246,40141.4991025665
,584760.73,295.9752,-0.019,1.357207e+04,0.5,135845,22315.67,1.38080296198326E-11,-8.40553648492812E-11,0.000305464650135524,0.00185949359341038,86.0215412626057,523.649806293903,6.0874264586275,246274.48432228,40456.2561857719
,584884.814,293.9809,-0.019,5.904585e+03,0.5,165510.5,21779.37,2.10654706620188E-11,-1.60085281714121E-10,0.000129699144114709,0.000985637793563243,131.234093759934,997.302514960425,7.59941632838783,300055.305954748,39483.9936369696
,585012.36,291.9716,-0.019,2.568774e+03,0.5,198535.4,17400.71,2.71431099657561E-11,-3.09692431762576E-10,4.50816222070396E-05,0.000514363948225301,169.096693605082,1929.32815405592,11.4096148950244,359926.410649767,31545.8859883805
,585135.757,289.9944,-0.019,1.117550e+03,0.5,230475.1,11559.3,3.09131736630962E-11,-6.16362304924992E-10,1.30288135811605E-05,0.000259774996150227,192.583512422271,3839.82631161699,19.9384997361432,417830.147606654,20955.947194424
,585261.306,287.9738,-0.019,4.861923e+02,0.5,264160.8,7402.148,3.46968888894711E-11,-1.23822948778568E-09,3.62970949970815E-06,0.000129533611758439,216.155377810224,7713.947022763,35.6870465167678,478899.221893783,13419.4131663086
,585385.062,285.9855,-0.019,2.115173e+02,0.5,300882.4,5394.849,4.4824529917275E-11,-2.49996100732041E-09,1.15089092665185E-06,6.41876768282546E-05,279.248760034346,15574.3074766612,55.772163409949,545472.103512459,9780.36479422554
,585509.972,283.9842,-0.019,9.202165e+01,0.5,343421.9,5348.517,7.84153216592288E-11,-5.03495431599516E-09,4.96396856027259E-07,3.18730503148644E-05,488.513351538684,31366.8598904674,64.2088077872801,622592.30245852,9696.3691417715
,585635.21,281.9723,-0.019,4.003407e+01,0.5,393631.3,6865.78,1.76102941087936E-10,-1.00963954036202E-08,2.77221107238829E-07,1.5893737467536E-05,1097.08965220526,62898.7276047448,57.3323497111763,713617.324307916,12447.0273397639
,585757.858,279.9810,-0.019,1.741690e+01,0.5,452429,8154.459,3.63915484502213E-10,-2.01909064400044E-08,1.43242645393887E-07,7.94744652133404E-06,2267.12802102084,125785.715940498,55.482405393172,820212.143747984,14783.2837804275
,585941.876,275.9916,-0.019,5.000000e+05,0.5,13274.17,64425.26,4.73955653496843E-12,-9.76537450834997E-13,0.0324885660261231,0.00669393881354894,29.5265848397117,6.08365269587978,0.206039835927709,24064.8486992991,116797.06786285
,586067.052,273.9771,-0.019,2.175258e+05,0.5,47974.52,132878.7,4.87125771758076E-12,-1.758718671971E-12,0.0291521441359223,0.0105250888358457,30.347059521932,10.9565010342223,0.361039955989937,86973.3900666857,240896.855386028
,586193.069,271.9854,-0.019,9.463495e+04,0.5,151710.9,235553.7,5.0463715307687E-12,-3.25016998954929E-12,0.0224825636307814,0.0144801374919312,31.4379870852074,20.247974516576,0.644060781044832,275037.901016372,427037.182065627
,586318.853,269.9885,-0.019,4.117107e+04,0.5,363136.9,309231.5,5.25465744727957E-12,-6.1706521359144E-12,0.0128404545171691,0.0150788093967005,32.7355708864345,38.4420530619619,1.17432053332212,658333.783252173,560608.253514706
,586446.04,267.9798,-0.019,1.791157e+04,0.5,610001.1,285509.6,5.59265944693535E-12,-1.1948909649819E-11,0.00515772466229211,0.0110196564931453,34.841262557205,74.4395581979866,2.1365344632895,1105875.8610072,517602.631742504
,586571.59,265.9844,-0.019,7.792469e+03,0.5,813998.3,226138.8,6.47122058546527E-12,-2.32934930029422E-11,0.00177726951169863,0.00639737347666353,40.3145404477176,145.11427225104,3.59955169126218,1475704.01245326,409968.834740029
,586696.266,263.9888,-0.019,3.390107e+03,0.5,1007649,197547.9,8.79589588086991E-12,-4.4865957514419E-11,0.000675447181485471,0.00344530960327421,54.7968494629437,279.506846514115,5.10078315183305,1826774.91150106,358136.164021123
,586821.457,261.9782,-0.019,1.474880e+03,0.5,1243534,197456.6,1.34402356115377E-11,-8.46433593557159E-11,0.000293718566515724,0.00184976862709864,83.7302507358791,527.312906322658,6.29775859606617,2254412.70997992,357970.645522697
,586946.414,259.9768,-0.019,6.416440e+02,0.5,1537873,188022.9,1.94289810102558E-11,-1.58913118099897E-10,0.000121677775403048,0.000995224334335932,121.03905753965,990.00014644851,8.17917923827364,2788022.23142669,340868.215527106
,587072.587,257.9748,-0.019,2.791500e+02,0.5,1868566,149164.8,2.42032604505611E-11,-3.03190763283718E-10,4.19959715936386E-05,0.000526077497216763,150.78195983496,1888.82392870819,12.5268562019994,3387538.20951927,270422.056012633
,587198.355,255.9740,-0.019,1.214445e+02,0.5,2212797,101589.2,2.71326632639968E-11,-5.9099860883423E-10,1.24431286795752E-05,0.000271033907273391,169.031612531882,3681.81504643909,21.7818134211117,4011597.3358231,184171.87119668
,587324.279,253.9808,-0.019,5.283509e+01,0.5,2589838,66882.07,3.00176461845906E-11,-1.16235697787775E-09,3.56395758639026E-06,0.00013800519014471,187.004537284978,7241.27493112955,38.7224558091578,4695137.97289739,121251.0383132
,587446.178,251.9898,-0.019,2.298591e+01,0.5,3007743,48756.17,3.73073952840752E-11,-2.30147398809033E-09,1.13029855522934E-06,6.97275353540106E-05,232.418363168917,14337.7690432363,61.689484633432,5452761.28159997,88390.4495879821
,587571.229,249.9717,-0.019,1.000008e+01,0.5,3511366,44159.84,5.69936853013497E-11,-4.53184814034333E-09,4.45381168052129E-07,3.54144464866388E-05,355.060409547228,28232.59889597,79.5149167207128,6365783.43639286,80057.7262597402
,587744.094,245.9805,-0.019,2.870762e+05,0.5,8464.003,121183.7,4.55266083742696E-12,-3.17977871495625E-13,0.0350869607175261,0.00245062777233261,28.362258255796,1.98094495351959,0.0698444015160455,15344.4585676855,219694.896578939
,587869.877,243.9824,-0.019,1.248930e+05,0.5,31194.62,271776.8,4.62791678385996E-12,-5.31193631921981E-13,0.034233767121933,0.00392936172821665,28.8310892678648,3.30924079574534,0.114780290297038,56552.9754803599,492706.329057083
,587996.675,241.9799,-0.019,5.433485e+04,0.5,113767.9,596125.7,4.74096710090701E-12,-9.0479217896373E-13,0.0326678780384546,0.0062345171192772,29.5353724118295,5.63669255496245,0.190845487788901,206250.733592909,1080721.03764407
,588122.536,239.9913,-0.019,2.363846e+04,0.5,395576.7,1246550,4.9070538675644E-12,-1.55719078709507E-12,0.029718956210869,0.00943093066891827,30.5700630986651,9.70101855470035,0.317337210701536,717144.155489045,2259880.4404427
,588250.067,237.9821,-0.019,1.028394e+04,0.5,1250681,2353046,5.12824821639891E-12,-2.72574467627662E-12,0.0244059116765522,0.0129721263509264,31.9480641117853,16.9808991287853,0.531515745973517,2267369.56330136,4265855.86688214
,588375.898,235.9920,-0.019,4.474074e+03,0.5,3285117,3605745,5.39085657351176E-12,-4.91149390048526E-12,0.0162704811765402,0.0148236867308232,33.5840669484857,30.597723705256,0.911078570447993,5955614.81919361,6536883.87848386
,588503.257,233.9819,-0.019,1.946446e+03,0.5,6448710,4053774,5.71305026712637E-12,-9.088272900295E-12,0.00795803213646378,0.0126595714064808,35.591275715623,56.6183057121821,1.59079169189008,11690917.8092232,7349119.227127
,588629.976,231.9810,-0.019,8.467957e+02,0.5,9667019,3540010,6.27778075676591E-12,-1.71432922092001E-11,0.00302337079408246,0.00825618653914544,39.1094451036003,106.799627372793,2.73078861359149,17525415.8721976,6417712.37252542
,588756.056,229.9738,-0.019,3.684033e+02,0.5,12640370,2978273,7.62917130317375E-12,-3.2379687176259E-11,0.0011066039035455,0.00469664224342745,47.528365170425,201.719627867991,4.24419453824414,22915827.6226053,5399334.88347728
,588882.308,227.9815,-0.019,1.602760e+02,0.5,15996580,2799626,1.05414176067246E-11,-6.02318417029201E-11,0.000452551991650968,0.0025858040104657,65.6711358962319,375.233541571248,5.71382748981471,29000327.5087055,5075464.31186461
,589009.168,225.9711,-0.019,6.972812e+01,0.5,20190180,2703548,1.48713678473074E-11,-1.11059834588973E-10,0.000190126790032934,0.00141987274262826,92.645947186493,691.882796223994,7.46803089865614,36602938.4068167,4901283.73911835
,589132.081,223.9811,-0.019,3.033521e+01,0.5,25009060,2271312,1.88968360869467E-11,-2.08070096714417E-10,6.94907174624502E-05,0.000765151384953483,117.723890369645,1296.23928270879,11.0108430721979,45339124.4056459,4117679.64617768
,589256.32,221.9903,-0.019,1.319742e+01,0.5,30403490,1691379,2.19981313637561E-11,-3.95428799184952E-10,2.25129135276769E-05,0.00040468229847337,137.044402199834,2463.4503040647,17.9755631351696,55118729.5914285,3066314.48355504
,589422.649,217.9815,-0.019,3.788642e+05,0.5,1586.08,95065.36,4.41767098192691E-12,-7.37048656946613E-14,0.0363253870007217,0.000606056399661293,27.5212957329279,0.459168058019055,0.0166841002863714,2875.41708634018,172344.749611041
,589548.074,215.9754,-0.019,1.648255e+05,0.5,5255.704,217339.4,4.44020904276018E-12,-1.0737318878616E-13,0.0361299354270626,0.000873694535568583,27.6617037986206,0.668915655887637,0.0241820120972083,9528.10771357463,394016.332275121
,589674.668,213.9831,-0.019,7.170755e+04,0.5,18460.74,495693.1,4.47136561464895E-12,-1.66523839159703E-13,0.0358494390182824,0.00133511475722048,27.8558036382155,1.03741356992089,0.0372422775301895,33467.6228326968,898645.975815175
,589800.249,211.9909,-0.019,3.119651e+04,0.5,64382.86,1125181,4.51931098970899E-12,-2.58594987603679E-13,0.0354023954879467,0.00202572516987498,28.1544947022291,1.61100026643212,0.057220002826212,116720.200564567,2039849.61201537
,589927.952,209.9849,-0.019,1.357207e+04,0.5,225878,2534794,4.58982133211112E-12,-4.09003517782745E-13,0.0346971416218121,0.00309189660195333,28.5937614546464,2.54801835961921,0.0891109889008732,409496.028339269,4595348.26613574
,590054.219,207.9926,-0.019,5.904585e+03,0.5,784691.6,5627190,4.69869421049819E-12,-6.55216169695099E-13,0.0335106904731793,0.00467294641277509,29.2720199070399,4.08187890156313,0.139446437742461,1422573.66220343,10201577.6468291
,590182.28,205.9768,-0.019,2.568774e+03,0.5,2656347,12178970,4.85621173681719E-12,-1.05918509352262E-12,0.031553179405373,0.00688204285369982,30.25332576768,6.59853264627463,0.218109331084648,4815712.6696311,22079351.8813834
,590308.828,203.9855,-0.019,1.117550e+03,0.5,8561433,25098590,5.08274764444756E-12,-1.73378677502782E-12,0.0282893298261987,0.00964983299547513,31.6646037314597,10.8011798000781,0.341112110281892,15521090.1920185,45501434.0569498
,590436.047,201.9802,-0.019,4.861923e+02,0.5,25364850,47250860,5.37809283655959E-12,-2.88702720088922E-12,0.0231698819601256,0.0124378811398627,33.5045511627345,17.9856602516883,0.536812451667546,45984138.9352717,85661461.0790552
,590562.922,199.9687,-0.019,2.115173e+02,0.5,64785840,75300210,5.74204111379066E-12,-4.94026453407585E-12,0.0160639025233104,0.0138208567897857,35.7718834765586,30.7769595783461,0.86036732168476,117450766.221692,136512351.482273
,590689.502,197.9780,-0.019,9.202165e+01,0.5,132118900,93707920,6.17728952254278E-12,-8.70936732668784E-12,0.00869704945742042,0.0122619796444098,38.4834027869733,54.2577921318907,1.40990110547753,239519407.904059,169883835.804877
,590815.644,195.9824,-0.019,4.003407e+01,0.5,213045000,91825490,6.78276691891231E-12,-1.57367478054261E-11,0.00370765798067343,0.00860216476375536,42.2554180758577,98.0371086935784,2.32010741244071,386230980.25279,166471163.439145
,590940.96,193.9788,-0.019,1.741690e+01,0.5,295284300,81271490,7.91758151050749E-12,-2.87670069051662E-11,0.00142762913182872,0.00518701538327463,49.3251088937352,179.213279492112,3.63330732585314,535323263.358721,147337732.635381
,591101.297,189.9800,-0.019,5.000000e+05,0.5,412.3708,73079.84,4.35550695435181E-12,-2.4577009024262E-14,0.036852923946578,0.000207951601018687,27.1340250208619,0.153110346233282,0.00564274360753937,747.590313368664,132487.02499433
,591225.646,187.9893,-0.019,2.175258e+05,0.5,1266.833,167924.3,4.35683482595466E-12,-3.28682753661538E-14,0.0368407682911095,0.000277929406384491,27.1422974221401,0.204763444422171,0.00754407194194051,2296.65165296807,304431.303232948
,591353.161,185.9726,-0.019,9.463495e+04,0.5,3783.903,384826.8,4.36979731297329E-12,-4.29670936690261E-14,0.0367300238452209,0.000361156882571595,27.2230513850616,0.267677266253516,0.00983274293786192,6859.8679380951,697655.576012317
,591478.773,183.9801,-0.019,4.117107e+04,0.5,11848.09,881588.4,4.38413095875962E-12,-5.89204419785586E-14,0.036606864931496,0.000491977242811054,27.3123474205134,0.367063757133727,0.013439480374288,21479.4968894988,1598238.64400239
,591606.429,181.9722,-0.019,1.791157e+04,0.5,37649.92,2017234,4.40331254117588E-12,-8.21840029021266E-14,0.0364412879686503,0.000680144979073645,27.4318452293052,0.511991557913322,0.0186641311816081,68255.8403531606,3657059.61284825
,591732.758,179.9781,-0.019,7.792469e+03,0.5,122182.1,4606903,4.43028681406434E-12,-1.1749796914428E-13,0.0362065609495273,0.000960253265716956,27.5998900982828,0.731991216654095,0.026521526500558,221504.903904548,8351891.20429729
,591859.322,177.9880,-0.019,3.390107e+03,0.5,400746.3,10496080,4.46627795407395E-12,-1.70525030760694E-13,0.0358877398982526,0.00137021430663516,27.8241084278103,1.06234027401123,0.0381805683645704,726516.16457405,19028427.1736567
,591986.946,175.9815,-0.019,1.474880e+03,0.5,1339622,23811980,4.51748651788549E-12,-2.54146203888244E-13,0.0354205462440916,0.00199270043904801,28.143128570886,1.58328514396482,0.0562583203916684,2428611.41180597,43168928.5228934
,592114.274,173.9747,-0.019,6.416440e+02,0.5,4482360,53643520,4.59182160502923E-12,-3.83684692755412E-13,0.0347150489562118,0.00290072960982734,28.6062227951923,2.39028663309675,0.0835582750721802,8126106.2059466,97250765.3960906
,592240.245,171.9826,-0.019,2.791500e+02,0.5,14842910,119387100,4.70288431193584E-12,-5.84690377624347E-13,0.0336123352174702,0.00417888420543543,29.2981234854387,3.64251590048885,0.124325911258419,26908829.9612942,216437826.104991
,592367.963,169.9735,-0.019,1.214445e+02,0.5,47864150,260621600,4.86435708510379E-12,-8.93357715457853E-13,0.0319221738676629,0.00586262887775955,30.3040698226266,5.565457903722,0.183653810735564,86773299.4131125,472482977.97672
,592494.496,167.9836,-0.019,5.283509e+01,0.5,148621800,551451700,5.09262790952111E-12,-1.37251463118758E-12,0.0293853116349839,0.00791963812742304,31.7261560059775,8.55051931599665,0.269510094900424,269437646.980375,999731186.618166
,592621.512,165.9821,-0.019,2.298591e+01,0.5,439614100,1109668000,5.39329058221637E-12,-2.1366450013333E-12,0.0257250751481141,0.0101914318144441,33.5992303849775,13.3109140989778,0.396167232000923,796979909.295913,2011725970.54684
,592748.372,163.9908,-0.019,1.000008e+01,0.5,1203585000,2045990000,5.77901020903211E-12,-3.39959139704393E-12,0.0206351611786405,0.0121389500765859,36.0021942913027,21.1788430129656,0.588265338540267,2181988849.15184,3709191594.67439
,592904.529,159.9835,-0.019,2.870762e+05,0.5,316.1971,128565.1,4.31218345684558E-12,-1.06055212785005E-14,0.037224136689545,9.15502268596821E-05,26.8641274227992,0.0660704902428386,0.00245943183647817,573.236245328871,233076.695530512
,593029.673,157.9913,-0.019,1.248930e+05,0.5,1053.088,295174.5,4.31715672516751E-12,-1.5402231362781E-14,0.0371810069635561,0.000132649914749538,26.8951099900403,0.0959531314161338,0.0035676794574057,1909.15163713042,535124.206062696
,593157.406,155.9761,-0.019,5.433485e+04,0.5,3532.692,677402.3,4.323972588319E-12,-2.25497660267375E-14,0.0371218615794767,0.000193592645650782,26.9375715916931,0.140480986942916,0.00521505758099729,6404.44551193967,1228068.03423922
,593284.453,153.9684,-0.019,2.363846e+04,0.5,9493.578,1554170,4.33197473601646E-12,-2.64616741092684E-14,0.0370529141825408,0.000226336070648164,26.9874235327229,0.164851470770212,0.00610845531698592,17210.9832995204,2817567.19275025
,593411.079,151.9756,-0.019,1.028394e+04,0.5,26759.83,3563687,4.34246005741948E-12,-3.26076596845726E-14,0.0369627411299555,0.000277554305126017,27.0527451993585,0.203139855595665,0.00750902927221162,48513.1093069446,6460636.59472939
,593537.393,149.9852,-0.019,4.474074e+03,0.5,74565.5,8171489,4.35293059060452E-12,-3.97208447510266E-14,0.0368728398593925,0.000336467654858928,27.1179747380557,0.247453719307521,0.00912508112046654,135180.389861482,14814157.6032992
,593664.051,147.9912,-0.019,1.946446e+03,0.5,219807.6,18726770,4.36571749127076E-12,-5.12431072755337E-14,0.0367628381533272,0.000431508008250824,27.1976348295797,0.31923534264405,0.0117376141213888,398490.951747345,33949910.7421837
,593792.112,145.9774,-0.019,8.467957e+02,0.5,666291.4,42876600,4.38240352006599E-12,-6.81014300749056E-14,0.0366190661013828,0.000569050923333074,27.3015857881188,0.424259661843191,0.0155397442894259,1207924.9949823,77731330.2255709
,593918.878,143.9681,-0.019,3.684033e+02,0.5,2054626,98038840,4.40461475758902E-12,-9.23086809363115E-14,0.0364272056467196,0.000763414620461614,27.4399578033654,0.575066481220069,0.0209572655082414,3724847.86797563,177735395.226578
,594045.536,141.9776,-0.019,1.602760e+02,0.5,6472247,223774400,4.43386505890599E-12,-1.282410759493E-13,0.0361725281878724,0.00104622127037933,27.6221819201262,0.798918839983443,0.0289230895044295,11733588.2243102,405682395.115961
,594171.943,139.9863,-0.019,6.972812e+01,0.5,20651680,509432100,4.47317435892111E-12,-1.81336365424644E-13,0.0358257703997623,0.00145232769205035,27.8670717897422,1.12969294463145,0.0405386311541813,37439595.4388365,923553518.530062
,594300.207,137.9711,-0.019,3.033521e+01,0.5,65777680,1155188000,4.52705729279341E-12,-2.57775639936557E-13,0.0353429396419395,0.00201246600036255,28.2027527773314,1.60589587781938,0.0569411039588361,119248880.870963,2094249541.72245
,594426.365,135.9883,-0.019,1.319742e+01,0.5,210087800,2602452000,4.6039431603072E-12,-3.7166191340858E-13,0.0346396501528811,0.0027963504776989,28.6817379046047,2.31538687997128,0.0807268683533836,380869848.779141,4718005994.1366
,594583.38,131.9775,-0.019,3.788642e+05,0.5,2.112382,97886.34,4.29155267094658E-12,-9.2611477905492E-17,0.0374033105495443,8.07161448116943E-07,26.7356013369381,0.000576952851882335,2.15799467014499E-05,3.82955418117463,177458.926759876
,594707.885,129.9868,-0.019,1.648255e+05,0.5,103.6532,225065.9,4.29028336198564E-12,-1.9758728415836E-15,0.0374143686502941,1.72310378275103E-05,26.727693770387,0.0123093324573855,0.000460546000082642,187.913713264045,408023.765770031
,594835.259,127.9784,-0.019,7.170755e+04,0.5,985.2749,517240.3,4.29102524025654E-12,-8.17384002076256E-15,0.0374077722539372,7.12568975517196E-05,26.7323155385935,0.0509215533264832,0.00190486878149286,1786.21272710211,937709.066606806
,594962.275,125.9699,-0.019,3.119651e+04,0.5,3360.934,1187998,4.29432634711684E-12,-1.21489660985295E-14,0.0373788528555758,0.000105747532776404,26.7528808406543,0.0756858738948243,0.00282907378631951,6093.06406339003,2153731.05249292
,595088.792,123.9763,-0.019,1.357207e+04,0.5,9966.994,2727358,4.29957484975739E-12,-1.57125821876273E-14,0.0373330246084622,0.000136431679403436,26.7855780682017,0.0978865612406944,0.00365445020419028,18069.2429430105,4944449.07808344
,595216.089,121.9688,-0.019,5.904585e+03,0.5,26473.05,6257392,4.30756220095464E-12,-1.82239357105935E-14,0.0372636300678222,0.000157650654133058,26.8353378296963,0.113531842040972,0.00423068428508235,47993.2035569063,11344075.8806166
,595340.11,119.9843,-0.019,2.568774e+03,0.5,62595.45,14366010,4.31268278105245E-12,-1.87911827561884E-14,0.0372193453854787,0.000162171798092126,26.8672381228083,0.117065689119967,0.00435719103634203,113479.79071494,26044254.1464075
,595463.787,117.9919,-0.019,1.117550e+03,0.5,161877,32969900,4.31939634323991E-12,-2.12075536126785E-14,0.0371613056923433,0.000182456139738351,26.9090624078532,0.132119244990007,0.00490984200740676,293468.104815324,59771394.7562085
,595589.415,115.9824,-0.019,4.861923e+02,0.5,434739.5,75669500,4.3258871657458E-12,-2.48532635142659E-14,0.0371052163491146,0.000213178403491577,26.9494990647398,0.154831362023741,0.00574524081697381,788142.708064529,137181840.269607
,595712.391,113.9900,-0.019,2.115173e+02,0.5,1153303,173566000,4.33496692163668E-12,-2.88047794822969E-14,0.0370270853874232,0.00024603579421414,27.0060643110151,0.179448595854526,0.00664475185232131,2090832.21018321,314659186.174544
,595838.611,111.9814,-0.019,9.202165e+01,0.5,3252364,398133600,4.34381216274047E-12,-3.54847174437406E-14,0.0369508533522122,0.00030185250682689,27.0611685723425,0.221063408018359,0.0081690266784818,5896236.64417791,721779579.898951
,595963.521,109.9898,-0.019,4.003407e+01,0.5,9259426,912800500,4.35479307662305E-12,-4.4174914713898E-14,0.0368563462997877,0.00037386987758361,27.1295776909972,0.275201774145654,0.0101439756003639,16786487.270568,1654823309.11421
,596091.192,107.9800,-0.019,1.741690e+01,0.5,27753350,2090443000,4.37051322441107E-12,-5.80242480645054E-14,0.0367210854043333,0.000487520174243618,27.2275113845677,0.361480630222825,0.0132763007649575,50314269.6416192,3789780793.03707
,596261.826,103.9809,-0.019,5.000000e+05,0.5,-59.14048,74279.06,4.2853219251803E-12,3.41194403388636E-15,0.0374576702549335,-2.98235410970264E-05,26.6967849113663,-0.0212557977189663,-0.000796193166687893,-107.216248036896,134661.100500156
,596386.565,101.9803,-0.019,2.175258e+05,0.5,-67.54955,171166.3,4.27455616572342E-12,1.68692286650084E-15,0.0375520278932027,-1.48196378946866E-05,26.6297161660898,-0.010509226078072,-0.000394642812282558,-122.461118130605,310308.750898838
,596509.275,99.9832,-0.019,9.463495e+04,0.5,-50.08335,393416,4.27480751331777E-12,5.4419922136396E-16,0.0375498251709377,-4.7802352636265E-06,26.6312820163996,-0.00339026327901267,-0.000127303795473494,-90.7965047987211,713227.005220172
,596631.065,97.9760,-0.019,4.117107e+04,0.5,575.0602,904435.3,4.27415375012196E-12,-2.7176025862501E-15,0.0375555541184266,2.38786615940943E-05,26.6272091892641,0.016930175372213,0.000635822374469462,1042.53122462562,1639657.97129351
,596753.37,95.9775,-0.019,1.791157e+04,0.5,3119.231,2078503,4.27499309854829E-12,-6.41552646196703E-15,0.0375481111099176,5.63488396049943E-05,26.6324381790097,0.0399675760744875,0.00150071036702858,5654.87876629298,3768134.67177528
,596874.785,93.9935,-0.019,7.792469e+03,0.5,10637.19,4773314,4.27882103192215E-12,-9.53522694977787E-15,0.0375144178794804,8.35997779998195E-05,26.6562855155042,0.059402749059179,0.00222847061810725,19284.2466184852,8653579.03388657
,596997.698,91.9821,-0.019,3.390107e+03,0.5,27095.44,10961900,4.28269379888257E-12,-1.05858904812117E-14,0.0374804513676206,9.26435491296475E-05,26.68041215718,0.0659481939061787,0.00247178317627419,49121.5393535668,19872915.9681431
,597122.78,89.9842,-0.019,1.474880e+03,0.5,71796,25166180,4.28789272714411E-12,-1.2232827796592E-14,0.0374349315964961,0.000106797231399522,26.7128005452617,0.0762083171918666,0.00285287636025809,130159.541215374,45623968.5072081
,597248.22,87.9821,-0.019,6.416440e+02,0.5,170981,57787840,4.29223718362933E-12,-1.26997480074377E-14,0.0373970182171814,0.000110649222601016,26.7398657278472,0.0791171461333915,0.00295877125706723,309972.819050446,104764036.189027
,597374.612,85.9808,-0.019,2.791500e+02,0.5,389082.3,132679600,4.29709859977177E-12,-1.2601221337161E-14,0.0373547158086582,0.000109542527582832,26.770151476126,0.0785033426968388,0.00293249527433004,705370.40591429,240535905.407534
,597499.741,83.9848,-0.019,1.214445e+02,0.5,930746.9,304693800,4.3010527475608E-12,-1.31384081708545E-14,0.0373203466635111,0.000114002309741742,26.7947851057282,0.081849920061789,0.00305469589469822,1687358.48085731,552381820.981236
,597627.334,81.9733,-0.019,5.283509e+01,0.5,2049745,699708500,4.30507570369889E-12,-1.26114051755528E-14,0.0372854999379767,0.000109225151717277,26.8198473989705,0.0785667861785341,0.0029294270399745,3715999.06413318,1268507122.18643
,597754.022,79.9690,-0.019,2.298591e+01,0.5,6037246,1607023000,4.30856529245138E-12,-1.6186369813992E-14,0.0372550956139565,0.000139959525765951,26.8415869093226,0.100838172945851,0.00375678879518215,10944971.4408094,2913384818.13128
,597879.369,77.9748,-0.019,1.000008e+01,0.5,17573190,3688540000,4.31475138229582E-12,-2.05566283255291E-14,0.0372013633565474,0.000177237233844189,26.8801251365323,0.128064097515022,0.00476426716261719,31858576.3564905,6686983594.55338
,598062.421,73.9936,-0.019,2.870762e+05,0.5,-130.0872,129417.4,4.28380643275358E-12,4.30597728109899E-15,0.0374709076382744,-3.76648383920689E-05,26.6873436660976,-0.0268254640640313,-0.00100517550190314,-235.836122764396,234621.83700048
,598185.708,71.9705,-0.019,1.248930e+05,0.5,-314.4793,298743.5,4.26563050097084E-12,4.4903152503869E-15,0.0376305682022571,-3.96126936547509E-05,26.574110879894,-0.0279738564609153,-0.00105267327992073,-570.122032003619,541594.474637514
,598307.561,69.9815,-0.019,5.433485e+04,0.5,125.2413,687272.5,4.26199002662316E-12,-7.76660162484777E-16,0.0376627516800296,6.8632630899448E-06,26.5514313794195,0.00483845313586575,0.000182229465022971,227.050951991991,1245961.79856737
,598429.944,67.9834,-0.019,2.363846e+04,0.5,490.4129,1579679,4.26217968494141E-12,-1.32319787729862E-15,0.0376610733851264,1.16919172920021E-05,26.5526129166337,0.00824328480851095,0.000310450984029034,889.073459107762,2863812.66237061
,598552.014,65.9815,-0.019,1.028394e+04,0.5,3711.066,3629778,4.26362847896614E-12,-4.35911140706759E-15,0.0376482403121284,3.84913635440429E-05,26.5616386428532,0.0271564801130478,0.00102239475802652,6727.82115967424,6580453.49592814
,598675.349,63.9754,-0.019,4.474074e+03,0.5,11286.03,8340408,4.2651176185605E-12,-5.77144971764E-15,0.0376350660872206,5.09268233535283E-05,26.5709157147156,0.0359550937896266,0.00135317480871439,20460.5338311736,15120392.2060983
,598797.685,61.9711,-0.019,1.946446e+03,0.5,33749.28,19159320,4.26772960906834E-12,-7.51763640571472E-15,0.0376119843565017,6.6253781000745E-05,26.5871879458329,0.0468335228179569,0.00176150719336594,61184.338976394,34734084.0882296
,598919.787,59.9814,-0.019,8.467957e+02,0.5,81208.12,43944640,4.27691059321402E-12,-7.90357751668908E-15,0.037531233282524,6.93563742052548E-05,26.6443838259304,0.0492378665307581,0.00184796416582318,147222.848656792,79667588.462794
,599047.505,60.0058,-0.019,3.684033e+02,0.5,200210.6,100886000,4.2821727483786E-12,-8.49807084487965E-15,0.0374850933454022,7.43900345909144E-05,26.6771661062472,0.0529414530502886,0.00198452312511151,362963.39409514,182897034.306287
,599175.722,58.9897,-0.019,1.602760e+02,0.5,456854.5,231955600,4.28104192798618E-12,-8.43184329022089E-15,0.037494997101254,7.38492976810856E-05,26.6701212985718,0.0525288672952858,0.00196957736739273,828235.16800628,420514157.868638
,599303.144,57.9886,-0.019,6.972812e+01,0.5,1041431,532825500,4.28379420309478E-12,-8.37286518892809E-15,0.0374709093245961,7.32385491475604E-05,26.6872674775227,0.0521614443309939,0.00195454421757217,1888018.56882651,965963600.031368
,599428.771,56.9943,-0.019,3.033521e+01,0.5,2279996,1223655000,4.28759734463936E-12,-7.9889387085317E-15,0.0374376853010571,6.97564041626675E-05,26.7109603653794,0.0497696514043775,0.00186326701562123,4133422.93906188,2218373912.27782
,599554.492,55.9945,-0.019,1.319742e+01,0.5,6567432,2810671000,4.29063269135322E-12,-1.00255200403887E-14,0.0374111261744111,8.74150788882316E-05,26.7298700295228,0.0624571868382066,0.00233660645447297,11906149.8702318,5095487880.48576
,599750.211,53.9833,-0.019,3.788642e+05,0.5,-313.7202,98196.9,4.27793643587732E-12,1.36671837323859E-14,0.0375219785079567,-0.000119875501180912,26.6507746412328,-0.0851440967138725,-0.00319480757539189,-568.745853557235,178021.94346164
,599872.173,52.9835,-0.019,1.648255e+05,0.5,-349.5679,226472.6,4.2636256677555E-12,6.58104632111518E-15,0.0376482147921591,-5.81112566537584E-05,26.5616211295165,-0.0409987350294945,-0.00154353286004576,-633.73443489361,410573.983423211
,599994.197,51.9894,-0.019,7.170755e+04,0.5,-184.584,521116.8,4.25911994698848E-12,1.50861648731133E-15,0.0376881278819545,-1.33494552410567E-05,26.5335512994575,-0.00939840940276548,-0.000354208499898679,-334.633806280274,944736.804384974
,600116.049,50.9962,-0.019,3.119651e+04,0.5,-145.9904,1198087,4.25819816744922E-12,5.18873882902643E-16,0.0376962904661273,-4.59340308647545E-06,26.5278087787029,-0.00323249097496789,-0.000121852920530813,-264.667160926081,2172021.48108674
,600237.98,50.0017,-0.019,1.357207e+04,0.5,1345.897,2753798,4.25834925770507E-12,-2.0812345316895E-15,0.0376949445216704,1.84231061054161E-05,26.5287500438244,0.0129657168382478,0.000488742093646665,2439.98740937027,4992382.36503167
,600361.423,48.9889,-0.019,5.904585e+03,0.5,5753.924,6328226,4.25941889792486E-12,-3.87286620655194E-15,0.0376854562810791,3.4265408875513E-05,26.535413710027,0.024127259961331,0.000909247552157587,10431.3347265604,11472491.4043568
,600483.338,47.9920,-0.019,2.568774e+03,0.5,17265.32,14540010,4.26114788382275E-12,-5.05983708274771E-15,0.0376701432129251,4.47308548630282E-05,26.546184981226,0.0315218750523597,0.00118743522184648,31300.4363771883,26359700.1346446
,600605.783,46.9925,-0.019,1.117550e+03,0.5,39149.3,33373490,4.26725831010068E-12,-5.00577481586805E-15,0.0376162033827934,4.41262820008934E-05,26.5842518380238,0.0311850768523863,0.00117306580762156,70974.0783177757,60503066.2872007
,600729.305,45.9840,-0.019,4.861923e+02,0.5,141495.7,76585210,4.27429011674337E-12,-7.89700350853233E-15,0.0375542429405821,6.93836824740406E-05,26.628058728791,0.0491969116422269,0.0018475590783129,256518.683435681,138841938.234484
,600851.173,44.9894,-0.019,2.115173e+02,0.5,311048,175862600,4.27853185113773E-12,-7.56743489083347E-15,0.0375170223814241,6.63563189540994E-05,26.6544839712242,0.0471437584243685,0.0017686989729482,563901.400857423,318822710.637679
,600973.556,43.9915,-0.019,9.202165e+01,0.5,662700.9,403888400,4.28219361339174E-12,-7.02623190358762E-15,0.0374849574089191,6.15053935972223E-05,26.6772960915266,0.0437721611450618,0.00164080201362555,1201415.74888594,732212502.7329
,601096.594,42.9951,-0.019,4.003407e+01,0.5,1339800,929051100,4.27905210416391E-12,-6.17089200923266E-15,0.037512500345693,5.40973989085847E-05,26.6577250540138,0.0384435474295953,0.00144211658540634,2428934.10942612,1684284151.50758
,601223.204,41.9860,-0.019,1.741690e+01,0.5,3337485,2134461000,4.28112614957231E-12,-6.69405264715793E-15,0.0374943132499755,5.86268421194365E-05,26.6706459839068,0.0417027441174139,0.00156361957421569,6050553.18420513,3869581376.42915
,601428.876,39.9896,-0.019,5.000000e+05,0.5,-227.1212,74405.38,4.27800947067835E-12,1.30585536232976E-14,0.037521371288665,-0.000114533369397847,26.6512296349084,-0.0813524405917416,-0.00305248357040848,-411.749835537984,134890.107035984
,601550.775,38.9903,-0.019,2.175258e+05,0.5,-16.60299,171348.2,4.27001900288699E-12,4.13748628843155E-16,0.0375919347783417,-3.64251574983256E-06,26.601450457593,-0.00257757954815348,-9.68962031699195E-05,-30.0996930358716,310638.518860105
,601674.187,37.9826,-0.019,9.463495e+04,0.5,-305.925,394912.3,4.25860802681749E-12,3.29899742450195E-15,0.0376926404184194,-2.91991944034282E-05,26.5303621288572,-0.0205521606550888,-0.000774665666275778,-554.613873284211,715939.659428213
,601796.617,36.9825,-0.019,4.117107e+04,0.5,-343.7571,908077.6,4.25701122685343E-12,1.61151187300576E-15,0.0377067961086115,-1.42740872372445E-05,26.5204143522534,-0.0100394291506904,-0.000378554762280228,-623.199989212871,1646261.12602314
,601918.61,35.9869,-0.019,1.791157e+04,0.5,325.1002,2087450,4.25667957378622E-12,-6.62936779694754E-16,0.0377097384686948,5.87292798300336E-06,26.5183482132899,0.00412997691336808,0.000155740353062349,589.376746351137,3784354.75945779
,602041.039,34.9890,-0.019,7.792469e+03,0.5,2729.602,4796554,4.25810929030617E-12,-2.42318623641854E-15,0.0376970656314446,2.14524814568381E-05,26.5272550900856,0.0150960144613003,0.000569075632214294,4948.51724358692,8695711.01530399
,602162.938,33.9936,-0.019,3.390107e+03,0.5,7471.695,11025080,4.25817557983941E-12,-2.88576492769288E-15,0.037696473673736,2.55468943414184E-05,26.527668061956,0.0179777965166853,0.000677699844354871,13545.4954774807,19987455.4942168
,602405.426,31.9937,-0.019,1.474880e+03,0.5,26094.28,25329760,4.26023159860534E-12,-4.38881679885065E-15,0.0376782583989967,3.88154891548823E-05,26.5404766891084,0.0273415393615679,0.00103018267839885,47306.5284019374,45920523.9943106
,602527.294,30.9924,-0.019,6.416440e+02,0.5,77811.4,58111120,4.2683886027429E-12,-5.71541716840889E-15,0.0376062267297205,5.03551325556447E-05,26.5912933579104,0.0356060210849439,0.00133901050263702,141064.907868487,105350113.080276
,602649.646,29.9902,-0.019,2.791500e+02,0.5,193621.4,133461900,4.27193848064039E-12,-6.19756431862176E-15,0.0375749651474949,5.45123166747151E-05,26.6134084587932,0.0386097111202777,0.00145076160312419,351017.780844035,241954143.319016
,602771.171,28.9987,-0.019,1.214445e+02,0.5,462925.4,306506500,4.27564617646608E-12,-6.45762884799842E-15,0.0375423747861606,5.6701306056587E-05,26.6365067369864,0.0402298663676696,0.00151032816596059,839241.151052194,555668079.273635
,602894.474,27.9894,-0.019,5.283509e+01,0.5,1242284,703884200,4.27955980576149E-12,-7.5529876558397E-15,0.0375080112581779,6.61978238151308E-05,26.6608879436604,0.0470537547485825,0.0017648982602536,2252146.57500695,1276077282.03173
,603016.966,26.9898,-0.019,2.298591e+01,0.5,2098136,1617844000,4.27980052321135E-12,-5.55035191932508E-15,0.037505955364961,4.8640409808126E-05,26.6623875700818,0.0345776942688796,0.00129687163904554,3803727.4941147,2933002295.36527
,603138.896,25.9942,-0.019,1.000008e+01,0.5,5613685,3717481000,4.28124797856942E-12,-6.46501691833139E-15,0.0374932524663041,5.6617722853541E-05,26.6714049566488,0.0402758927171558,0.00151007765742448,10177094.3245811,6739450964.35551
,603349.732,23.9902,-0.019,2.870762e+05,0.5,-148.0736,129632.2,4.27670692487774E-12,4.88510871921927E-15,0.0375330998238747,-4.28725363766139E-05,26.6431150088235,-0.0304333487711428,-0.0011422594077706,-268.44381082663,235011.249634235
,603472.239,22.9912,-0.019,1.248930e+05,0.5,-385.7225,299224,4.25877830690112E-12,5.48988923175837E-15,0.0376910933283977,-4.85866867175189E-05,26.5314229431546,-0.0342010225990928,-0.00128907607678528,-699.279397688548,542465.576921123
,603594.497,21.9904,-0.019,5.433485e+04,0.5,-132.6723,688385.6,4.25509849282135E-12,8.20083545863164E-16,0.0377237499142017,-7.27048425438001E-06,26.5084983632242,-0.00510897300494837,-0.000192729627115965,-240.522671179292,1247979.7464381
,603717.847,20.9816,-0.019,2.363846e+04,0.5,-317.083,1582300,4.25511983888353E-12,8.52699338856541E-16,0.037723560557104,-7.55956503326058E-06,26.5086313453526,-0.00531216352959517,-0.000200393730645263,-574.842300506913,2868564.29418193
,603840.339,19.9855,-0.019,1.028394e+04,0.5,917.179,3636088,4.25623363499053E-12,-1.07360660938541E-15,0.0377136879500747,9.51302680253106E-06,26.5155700947915,0.00668837609650008,0.000252243345045554,1662.76112669752,6591892.94527168
,603909.994,20.0020,-0.019,4.474074e+03,0.5,3029.184,8356822,4.25674754943263E-12,-1.54298746207356E-15,0.0377091322449859,1.3668820521772E-05,26.5187716893421,0.00961253439417619,0.00036248037830649,5491.6318415643,15150149.2776553
,604063.889,19.4931,-0.019,1.946446e+03,0.5,12712.82,19204830,4.25762764569694E-12,-2.81837714193612E-15,0.0377013258053665,2.49567514383089E-05,26.5242545307902,0.0175579827306006,0.000661959517475552,23047.1728056386,34816589.5303254
,604216.052,18.9935,-0.019,8.467957e+02,0.5,36706.93,44067500,4.26499819050209E-12,-3.55261791635302E-15,0.0376361627419778,3.13498154249365E-05,26.5701716993899,0.0221321707076074,0.000832970556532592,66546.2862586333,79890322.3370171
,604367.326,18.4988,-0.019,3.684033e+02,0.5,114627,101211700,4.26840402019358E-12,-4.83416786421658E-15,0.0376061100861056,4.25906844845015E-05,26.5913894058554,0.0301159964058008,0.00113254692886297,207808.202837131,183487498.434844
,604520.41,17.9964,-0.019,1.602760e+02,0.5,282599.3,232484800,4.27130734522085E-12,-5.19203176226691E-15,0.0375805408538772,4.56814146082974E-05,26.6094765986344,0.0323454241315581,0.00121556032910539,512326.525653041,421473548.770794
,604672.027,17.4981,-0.019,6.972812e+01,0.5,660191.6,534023600,4.27419316199314E-12,-5.28401071099725E-15,0.037555165608242,4.64279197982454E-05,26.6274547181336,0.0329184364404348,0.00123625922150257,1196866.61889581,968135645.080258
,604825.158,16.9964,-0.019,3.033521e+01,0.5,1228096,1227056000,4.27572408109557E-12,-4.27934800131139E-15,0.037541738786483,3.75735575529761E-05,26.6369920688176,0.0266595684400277,0.00100084755707971,2226425.03660978,2224539612.31227
,604978.054,16.4941,-0.019,1.319742e+01,0.5,3298227,2819672000,4.27695356717464E-12,-5.00283853334775E-15,0.0375309329916073,4.3900686508257E-05,26.6446515459765,0.0311667843403529,0.00116972009510326,5979382.0427901,5111805865.19911
,605246.423,15.5005,-0.019,3.788642e+05,0.5,-322.8599,98259.33,4.27521588743259E-12,1.40474779737954E-14,0.0375458336104931,-0.000123367868322534,26.633826113692,-0.0875132614448316,-0.00328579382741568,-585.315288607184,178135.12330673
,605400.302,14.9953,-0.019,1.648255e+05,0.5,-376.7307,226615.4,4.26093735183514E-12,7.08348113682035E-15,0.0376719534919943,-6.26267297341949E-05,26.5448734048057,-0.0441288135722632,-0.00166242320689591,-682.9780917286,410832.866682522
,605553.417,14.4921,-0.019,7.170755e+04,0.5,-303.511,521479,4.25616081224599E-12,2.47716902173547E-15,0.0377143228538281,-2.19504751748167E-05,26.5151164221896,-0.015432317505432,-0.000582019601939867,-550.237513424415,945393.439654742
,605704.504,13.9973,-0.019,3.119651e+04,0.5,-442.289,1198831,4.25555499415184E-12,1.57001709399275E-15,0.0377196994840924,-1.39160633693321E-05,26.5113422844148,-0.0097809241399593,-0.000368933569452241,-801.829256847267,2173370.28462265
,605857.182,13.4959,-0.019,1.357207e+04,0.5,226.3338,2755877,4.25513779867583E-12,-3.49464619610359E-16,0.0377234025965403,3.09813575083534E-06,26.5087432316287,0.00217710173162257,8.21276856695709E-05,410.322351795812,4996151.40071871
,606010.407,12.9949,-0.019,5.904585e+03,0.5,3599.32,6333888,4.25561345490164E-12,-2.41831156794951E-15,0.0377191742698905,2.14344456885095E-05,26.5117064843724,0.0150656461534102,0.000568263916254913,6525.23594472281,11482756.0893303
,606162.913,12.4946,-0.019,2.568774e+03,0.5,7775.252,14556000,4.25647173150759E-12,-2.27364250778702E-15,0.0377115699787921,2.01440615485534E-05,26.5170533932729,0.0141643839262264,0.000534161308051663,14095.8163846721,26388688.5332188
,606314.515,11.9968,-0.019,1.117550e+03,0.5,11577.68,33425840,4.26058047984941E-12,-1.47573366622777E-15,0.0376752085466852,1.3049530198397E-05,26.5426501565154,0.00919355534113981,0.000346369156317388,20989.2684430666,60597972.0198686
,606467.193,11.4956,-0.019,4.861923e+02,0.5,82665.97,76735420,4.26593278151967E-12,-4.59562834658521E-15,0.037627899758029,4.05359980118729E-05,26.5759940333504,0.0286299381104726,0.00107728569153593,149865.796553065,139114255.141916
,606619.154,10.9961,-0.019,2.115173e+02,0.5,186932.8,176252300,4.26908042033665E-12,-4.52777726247378E-15,0.0376001576451018,3.98786441313973E-05,26.5956032571013,0.028207238058959,0.0010605977907806,338891.96453988,319529200.876851
,606772.3,10.4949,-0.019,9.202165e+01,0.5,436771.5,404872400,4.27179271912188E-12,-4.60835886471872E-15,0.0375762826316548,4.05368440265423E-05,26.612500390747,0.0287092469489576,0.00107878803297039,791826.537076586,733996404.183621
,606925.056,9.9946,-0.019,4.003407e+01,0.5,751365.4,930254000,4.27352501422936E-12,-3.45172268189811E-15,0.0375610701032293,3.03380458052756E-05,26.6232922777265,0.0215036115421927,0.000807699187533727,1362156.32833453,1686464898.51477
,606999.344,10.0013,-0.019,1.741690e+01,0.5,2412398,2137871000,4.27430256934714E-12,-4.82317173004727E-15,0.0375542139032001,4.2376602943607E-05,26.6281363062729,0.030047492467497,0.00112841139619743,4373455.58121462,3875763392.63541
,607483.274,8.9996,-0.019,5.000000e+05,0.5,-233.121,74432.41,4.27645381646011E-12,1.33937781961782E-14,0.0375350020592616,-0.000117558966786876,26.6415381889013,-0.0834408293932021,-0.00313198242539775,-422.626920826635,134939.10993864
,607743.141,8.4996,-0.019,2.175258e+05,0.5,-27.00737,171412.6,4.26841468373334E-12,6.72521475533416E-16,0.0376060634391606,-5.92512376304241E-06,26.5914558377903,-0.0041896878447084,-0.000157557670789662,-48.9618765479114,310755.270133912
,608002.617,7.9994,-0.019,9.463495e+04,0.5,-345.0992,395023.3,4.25741068025813E-12,3.71934774436986E-15,0.0377032348797377,-3.29381993275069E-05,26.522902875126,-0.0231708675510627,-0.000873617328395566,-625.633093010648,716140.892213813
,608261.782,7.5026,-0.019,4.117107e+04,0.5,-424.0991,908359.6,4.25568932102834E-12,1.98691576653974E-15,0.0377185058088647,-1.76101891441278E-05,26.5121791166978,-0.0123781278938763,-0.000466884590640095,-768.852642011433,1646772.36607304
,608520.556,6.9981,-0.019,1.791157e+04,0.5,-157.5159,2088346,4.25485333429891E-12,3.20927208575635E-16,0.037725924689044,-2.84552127891019E-06,26.5069710697192,-0.00199931879311225,-7.54261506474502E-05,-285.561831830836,3785979.12500642
,608781.624,6.4970,-0.019,7.792469e+03,0.5,1522.686,4799056,4.25589026405126E-12,-1.35034567685961E-15,0.0377167293438118,1.19670901397299E-05,26.5134309555924,0.00841241071745094,0.000317288650101187,2760.48959795911,8700246.91106588
,609034.938,5.9291,-0.019,3.390107e+03,0.5,4254.704,11030710,4.25600355723256E-12,-1.64160197838322E-15,0.0377157235246925,1.45474987324844E-05,26.514136751737,0.0102268850957157,0.000385714428173708,7713.38682722178,19997662.1661351
,609317.191,5.5000,-0.019,1.474880e+03,0.5,14111.94,25344090,4.25782598638518E-12,-2.37081642506433E-15,0.0376995744099995,2.0991644683216E-05,26.5254901576079,0.0147697599548752,0.000556813837072075,25583.6486163419,45946502.9656407
,609577.198,5.0008,-0.019,6.416440e+02,0.5,50712.5,58157310,4.26500294500845E-12,-3.71903311636562E-15,0.037636118282536,3.2818258760646E-05,26.5702013191095,0.0231689074751797,0.000871988405240889,91937.0958533154,105433851.299797
,609836.487,4.4995,-0.019,2.791500e+02,0.5,129558,133585300,4.2679972272966E-12,-4.13932659337587E-15,0.0376097072776399,3.64758581631098E-05,26.5888551592658,0.0257872602503731,0.000969852221763922,234876.73186224,242177856.163547
,610095.761,3.9988,-0.019,1.214445e+02,0.5,309166.9,306885900,4.27036564442552E-12,-4.30210611876772E-15,0.0375888455037273,3.78682332390192E-05,26.6036099720372,0.0268013474189066,0.0010074327298843,560491.139659303,556355896.560631
,610354.754,3.4970,-0.019,5.283509e+01,0.5,721178.1,705303900,4.27095435562407E-12,-4.36708027188804E-15,0.0375836630821331,3.84295545971217E-05,26.607277536929,0.0272061247077396,0.00102250689383683,1307429.53131894,1278651067.48863
,610614.527,2.9980,-0.019,2.298591e+01,0.5,1167071,1620656000,4.27237961196799E-12,-3.07663708160097E-15,0.0375711450535134,2.70558303728545E-05,26.6161566276301,0.0191668957086296,0.000720122592332981,2115792.32722947,2938100192.60046
,610874.627,2.4998,-0.019,1.000008e+01,0.5,3832700,3722756000,4.27518683463746E-12,-4.4014457517804E-15,0.0375464543271232,3.86553122201845E-05,26.6336451200032,0.0274202154670992,0.00102953295891538,6948332.40871584,6749014053.94144
,611131.888,2.0006,-0.019,1.000008e+01,0.5,3094017,3722694000,4.27525961449425E-12,-3.55326704979208E-15,0.0375458290161525,3.12052060295767E-05,26.6340985254222,0.022136214692191,0.000831123106008713,5609168.10452625,6748901653.64678