File: Scripts/Data_examples/Nb-PrO2/Jan 31 2019 Pr0.994Nb0.006O2 1300C 10h air.dat
Comment,Time Stamp (sec),Temperature (K),Magnetic Field (Oe),Frequency (Hz),AC Voltage (Vrms),Re[Impedance] (Ohm),-Im[Impedance] (Ohm),Re[Cp] (F),Im[Cp] (F),Re[Modulus],Im[Modulus],Re[Permittivity],Im[Permittivity],Loss Factor,Re[Sp.Impedance] (Ohm-cm),-Im[Sp.Impedance] (Ohm-cm)
,647176.964,360.0416,-0.019,5.000000e+05,0.5,5294.106,2048.575,2.023576422312E-11,-5.22950249750218E-11,0.00103632241306825,0.00267815467090983,125.668508528262,324.763508785631,2.58428712641714,9628.02151975405,3725.60054234467
,647206.105,360.0416,-0.019,2.298591e+01,0.5,14159.19,411.5982,1.4203347515595E-08,-4.88602467429007E-07,9.57206669809845E-09,3.29284022794678E-07,88205.8853183366,3034327.86960812,34.4005148710563,25750.3317882729,748.544953027392
,647437.751,360.0053,-0.019,6.972812e+01,0.5,13529.93,949.7639,1.17843333849552E-08,-1.67874569453637E-07,6.70028921157137E-08,9.54494522399892E-07,73183.2800658515,1042537.68379843,14.2455719784675,24605.9404932138,1727.26939503771
,647534.846,357.9668,-0.019,2.115173e+02,0.5,13028.13,1316.43,5.77685545853971E-09,-5.71710033234315E-08,2.81722350404163E-07,2.78808246923193E-06,35875.5321248797,355044.397607248,9.89656115403022,23693.3518146696,2394.09947009936
,647677.478,355.9858,-0.019,6.416440e+02,0.5,13266.34,778.178,1.09297174554747E-09,-1.86329281820178E-08,5.05182295903432E-07,8.61232275833489E-06,6787.59287823449,115714.547191308,17.0479504689159,24126.5677355863,1415.21808029518
,647791.811,353.9790,-0.019,1.946446e+03,0.5,14035.55,477.5016,1.97966599978698E-10,-5.81897550150831E-09,9.4035025421071E-07,2.76403953630462E-05,1229.41575536396,36137.1067766027,29.393723497471,25525.4763394583,868.398872352951
,647907.985,351.9783,-0.019,5.904585e+03,0.5,15115.2,787.959,9.27107076807359E-11,-1.77844391489387E-09,4.70721545539724E-06,9.02972147680532E-05,575.753711615513,11044.5245270513,19.1827239742169,27488.9605299528,1433.0061031426
,648024.362,349.9805,-0.019,1.791157e+04,0.5,15837.1,2203.074,7.65668887655325E-11,-5.50411594920831E-10,3.9924104456494E-05,0.000286999907714376,475.497075757599,3418.17602971152,7.18863733129255,28801.8297348971,4006.5771032183
,648141.269,347.9778,-0.019,5.433485e+04,0.5,14042.23,4651.03,6.226025197974E-11,-1.87974013961953E-10,0.000255682427166961,0.000771947600689892,386.649741547608,1167.35961717127,3.01916564717923,25537.6247897824,8458.50402863518
,648257.022,345.9853,-0.019,1.648255e+05,0.5,10453.82,4304.208,3.25183933778311E-11,-7.89788576809109E-11,0.000717778807175994,0.00174330107885877,201.946313984937,490.475928686999,2.42874414991097,19011.6336778363,7827.76303487266
,648373.009,343.9898,-0.019,5.000000e+05,0.5,8873.232,3388.698,1.19561707257121E-11,-3.13069729674499E-11,0.00171425683146556,0.00448874422364542,74.2504274235827,194.423129068631,2.61847824739767,16137.1284681059,6162.78881985882
,648402.15,343.9898,-0.019,2.298591e+01,0.5,26013.21,931.5925,9.520118533623E-09,-2.65833873329838E-07,2.16649770223686E-08,6.04959353932164E-07,59122.0120941005,1650886.32232052,27.923378515821,47308.4115954386,1694.22233662142
,648519.493,341.9786,-0.019,6.972812e+01,0.5,27026.24,2101.553,6.52779130082524E-09,-8.39482298880948E-08,1.48258034375127E-07,1.90661725826112E-06,40539.0074579545,521336.813737493,12.8601277245922,49150.7386361432,3821.94793774505
,648636.026,339.9806,-0.019,2.115173e+02,0.5,27138.69,1907.241,1.93891048126614E-09,-2.75893243113128E-08,4.08158745476164E-07,5.80781016361672E-06,12041.0568962916,171335.720226663,14.2292924701178,49355.2436120346,3468.56624921323
,648753.838,337.9706,-0.019,6.416440e+02,0.5,28795.48,1074.077,3.20853611783927E-10,-8.60192868951837E-09,6.9727579658776E-07,1.86936236928329E-05,1992.57089597455,53419.8529375616,26.8095117947782,52368.3320869751,1953.34896389926
,648869.731,335.9713,-0.019,1.946446e+03,0.5,31004.12,1230.203,1.04479980562628E-10,-2.63315067103673E-09,2.42265513619384E-06,6.10568260369795E-05,648.843462673183,16352.439863937,25.202442198564,56385.0316863767,2237.28443625156
,648985.546,333.9904,-0.019,5.904585e+03,0.5,33274.81,3255.886,7.85113466587671E-11,-8.02377645567016E-10,1.9450449706408E-05,0.000198781535470001,487.572583291909,4982.94014908613,10.21989406263,60514.5772951519,5921.25289404216
,649102.734,331.9754,-0.019,1.791157e+04,0.5,32203.75,8384.012,6.72736428828951E-11,-2.58404159844957E-10,0.000151935055677884,0.000583596319910642,417.783992299,1604.74618142232,3.84109063775195,58566.7151388317,15247.4181585855
,649219.002,329.9829,-0.019,5.433485e+04,0.5,24554.38,10154.96,4.21298424703745E-11,-1.01868659389866E-10,0.000558251574507883,0.00134983508512735,261.635508765889,632.62658875377,2.41796915005081,44655.3391723208,18468.1178299493
,649335.535,327.9881,-0.019,1.648255e+05,0.5,20121.69,7644.543,1.59318017458888E-11,-4.19351131744871E-11,0.00127482011927528,0.003355535477506,98.9399630030435,260.426197374874,2.63216388474759,36593.9148807787,13902.5974381105
,649452.676,325.9748,-0.019,5.000000e+05,0.5,17275.75,8364.884,7.22709102727356E-12,-1.49258994881963E-11,0.00423158379454792,0.00873936610939987,44.8818112516741,92.6930906311563,2.06527071983305,31418.202198802,15212.6313984356
,649482.394,325.9748,-0.019,2.298591e+01,0.5,57518.93,2626.535,5.48552064789369E-09,-1.20128335681707E-07,6.10823084379135E-08,1.33765170587057E-06,34066.2794209755,746023.160314075,21.8991675344132,104605.668234302,4776.69610362679
,649598.708,323.9810,-0.019,6.972812e+01,0.5,59320.18,4051.746,2.61596029882674E-09,-3.82993494160927E-08,2.85838091043758E-07,4.18485438415244E-06,16245.6839039023,237847.311604081,14.6406462794065,107881.476040654,7368.62799509066
,649716.614,321.9817,-0.019,2.115173e+02,0.5,62293.26,2628.499,5.08771477513585E-10,-1.20574647086942E-08,5.62511425837297E-07,1.33310571937267E-05,3159.58182037933,74879.4851465276,23.6991758414213,113288.409377454,4780.26789351252
,649833.88,319.9720,-0.019,6.416440e+02,0.5,67884.62,2322.461,1.24859502237373E-10,-3.64959405681008E-09,1.50770926462349E-06,4.40697477802405E-05,775.404736324436,22664.7749398524,29.229606008454,123457.026024852,4223.69791741788
,649952.035,317.9749,-0.019,1.946446e+03,0.5,73541.16,5319.006,7.99985122276114E-11,-1.10606819911328E-09,1.04747892870899E-05,0.000144825584879612,496.808205772513,6868.92471075033,13.8261096152176,133744.180994426,9673.30541392653
,650066.852,315.9828,-0.019,5.904585e+03,0.5,75137.87,15203.09,6.97302426432683E-11,-3.44626119216446E-10,9.08222638713376E-05,0.000448868713917385,433.040012508223,2140.20335107148,4.94227620832344,136648.00616166,27648.7999459697
,650185.615,313.9706,-0.019,1.791157e+04,0.5,60968.35,23965.01,4.96203079331449E-11,-1.26236888746375E-10,0.000434293883247191,0.00110486836753558,308.152932694625,783.958606904498,2.54405693967998,110878.887922512,43583.493039452
,650297.889,311.9788,-0.019,5.433485e+04,0.5,47955,18676.46,2.06555744121665E-11,-5.30367141811373E-11,0.00102670647656254,0.00263624418565169,128.275621347958,329.369560491727,2.56767074702594,87212.4154634995,33965.5758295784
,650414.765,309.9699,-0.019,1.648255e+05,0.5,42065.95,18309.27,8.39965458499781E-12,-1.92983909128976E-11,0.00305329249442946,0.00701500657350319,52.1636866396786,119.847215863898,2.29752196564909,76502.4107656511,33297.7929741088
,650531.688,307.9749,-0.019,5.000000e+05,0.5,27992.54,24460,5.63427664460238E-12,-6.44798505090343E-12,0.0123736969472191,0.0141607198177804,34.990086598945,40.0433932430266,1.14442109566639,50908.0810834872,44483.6968457345
,650575.899,307.9749,-0.019,2.298591e+01,0.5,136703.9,6878.618,2.54215541476878E-09,-5.05221484322882E-08,1.5996812009076E-07,3.17916562485011E-06,15787.339479674,313753.558853742,19.8737449877286,248613.853034734,12509.6630347348
,650691.355,305.9707,-0.019,6.972812e+01,0.5,143657.9,6412.397,7.07802669456342E-10,-1.58570102737701E-08,4.52374684270613E-07,1.01346184828356E-05,4395.60892398985,98475.4916518179,22.4031512708898,261260.608057843,11661.7794032092
,650808.465,303.9734,-0.019,2.115173e+02,0.5,156658.8,4942.982,1.51396872348239E-10,-4.79824776740604E-09,1.05782191764505E-06,3.35257365355512E-05,940.20759157241,29798.1649633003,31.6931763053153,284904.438569769,8989.45677849233
,650923.188,301.9812,-0.019,6.416440e+02,0.5,172351.1,9777.466,8.13816952322932E-11,-1.43454599516383E-09,6.34739445473625E-06,0.000111887928468142,505.398073854757,8908.84345358486,17.6273791184751,313442.930638956,17781.5958079917
,651037.303,299.9705,-0.019,1.946446e+03,0.5,182200.9,29341.27,7.04428803501126E-11,-4.3743015208213E-10,5.77821534071615E-05,0.000358810656618575,437.465648068742,2716.53663243643,6.20971416711001,331356.075250204,53360.9223118906
,651151.386,297.9753,-0.019,5.904585e+03,0.5,157481.1,56706.41,5.45582026261074E-11,-1.51515247810297E-10,0.000338760379121366,0.000940781776530199,338.818335517674,940.942729005282,2.77713048665927,286399.898255634,103127.994752654
,651264.534,295.9814,-0.019,1.791157e+04,0.5,121259.5,48426.06,2.52387917320961E-11,-6.31982710556693E-11,0.000877577002795387,0.00219746451746161,156.738400341913,392.475044557831,2.50401333496882,220526.199413955,88069.099446989
,651377.494,293.9931,-0.019,5.433485e+04,0.5,106316,43909.05,9.72074640414088E-12,-2.3536625700229E-11,0.0024138249976017,0.00584454044086634,60.3679549198415,146.16757810196,2.42127761816755,193349.497704461,79854.3282495584
,651494.776,291.9844,-0.019,1.648255e+05,0.5,77906.2,58887.66,5.96214109849322E-12,-7.88769254623859E-12,0.00982023042385162,0.0129918022799118,37.0261963532195,48.9842907382156,1.3229630791918,141682.574946981,107094.882068466
,651609.546,289.9893,-0.019,5.000000e+05,0.5,26125.42,48733.57,5.07355197416002E-12,-2.71986386831007E-12,0.0246530836605106,0.0132161909116442,31.5078641213286,16.8909477280782,0.536086726254613,47512.4801000609,88628.3464468676
,651659.731,289.9893,-0.019,2.298591e+01,0.5,355473.3,14473.87,7.91793952750652E-10,-1.94461888426743E-08,3.36602174206802E-07,8.26683434716954E-06,4917.21310876836,120765.073237299,24.559658197842,646474.509973542,26322.6183673169
,651774.985,287.9907,-0.019,6.972812e+01,0.5,387541.6,11775.51,1.78795896896174E-10,-5.88431821267855E-09,8.30725642591288E-07,2.73398557422019E-05,1110.36150877087,36542.8992618984,32.9108123554733,704794.891639857,21415.2991432508
,651891.081,285.9713,-0.019,2.115173e+02,0.5,430466.2,20458.18,8.28855209002564E-11,-1.74401707370616E-09,4.37814889860565E-06,9.21218368113372E-05,514.737159183866,10830.7263360022,21.0412754213718,782858.869302343,37205.8657864051
,652005.773,283.9777,-0.019,6.416440e+02,0.5,465681.2,62439.59,7.01565449240573E-11,-5.23235082550813E-10,4.05349103051859E-05,0.000302313735128807,435.687442633335,3249.40396165994,7.45810790878031,846901.934896069,113554.529547504
,652120.589,281.9681,-0.019,1.946446e+03,0.5,424789.4,139421.7,5.70334588185056E-11,-1.73769282338672E-10,0.000274565008865917,0.00083654341739591,354.190216238078,1079.14513624237,3.04679544145567,772534.868883134,253556.5264316
,652236.014,279.9762,-0.019,5.904585e+03,0.5,326816.5,132587.4,2.87312760409398E-11,-7.0820116211901E-11,0.000792068443245063,0.00195238036481445,178.427489486829,439.808365032214,2.46491370974919,594358.385534914,241127.461453971
,652347.15,277.9885,-0.019,1.791157e+04,0.5,284354,115090.2,1.08673123949897E-11,-2.68499294359112E-11,0.00208566447006264,0.00515306285609193,67.488379748402,166.743916814612,2.47070558570582,517134.796928536,209306.52357788
,652461.576,275.9913,-0.019,5.433485e+04,0.5,217702.5,152055.4,6.31626544921553E-12,-9.04319595987939E-12,0.00835898580225091,0.0119678229554132,39.22538579317,56.1602189112493,1.43173146103328,395920.360284486,276532.555901754
,652575.66,273.9742,-0.019,1.648255e+05,0.5,81192.91,136273.8,5.22935984087639E-12,-3.11569019810038E-12,0.0227253064009314,0.0135399009738721,32.4754649498086,19.3491155517639,0.595807191110837,147659.885301022,247831.660147844
,652688.698,271.9836,-0.019,5.000000e+05,0.5,15708.52,63275.46,4.73850326148184E-12,-1.17636242001327E-12,0.032009458963037,0.0079465439889342,29.4271385533526,7.30546715121645,0.248256116984373,28567.9902524594,115074.668046378
,652747.698,271.9836,-0.019,2.298591e+01,0.5,1035159,30084.2,1.94231016394346E-10,-6.68324185784416E-09,6.99633693633581E-07,2.40735041871828E-05,1206.21696670681,41504.3893152967,34.4087261752016,1882571.51034888,54712.0373117926
,652866.165,269.9876,-0.019,6.972812e+01,0.5,1161166,49333.68,8.33656070213753E-11,-1.96217489639091E-09,3.48033783839451E-06,8.19166534192706E-05,517.718598685775,12185.5339873605,23.5369832536312,2111731.65705536,89719.7246690301
,652977.815,267.9744,-0.019,2.115173e+02,0.5,1271962,150934.3,6.92208175941752E-11,-5.83341557145873E-10,3.23006660077688E-05,0.000272205984567945,429.876371865814,3622.6782759862,8.42725609752058,2313228.61845029,274493.689485819
,653093.037,265.9747,-0.019,6.416440e+02,0.5,1203582,368261.4,5.76584568489206E-11,-1.88444080240659E-10,0.00023907016074036,0.000781348634975602,358.071590296866,1170.27883126682,3.2682817151078,2188870.67935335,669731.335960171
,653207.87,263.9730,-0.019,1.946446e+03,0.5,933207.6,380056.1,3.06071929565466E-11,-7.51543392717963E-11,0.000748449534513248,0.00183777814334311,190.077342603713,466.724835374536,2.45544697217069,1697159.60639965,691181.534618649
,653319.956,261.9782,-0.019,5.904585e+03,0.5,809826.2,329859.4,1.16282046878122E-11,-2.85479959496474E-11,0.00197055845010725,0.00483784867591539,72.21368681046,177.289280153013,2.45506479427295,1472774.45537748,599892.295638425
,653432.293,259.9754,-0.019,1.791157e+04,0.5,625447.2,428612.2,6.62467913728201E-12,-9.6669833880404E-12,0.00776730978810865,0.0113343534283559,41.1407020501529,60.03407486605,1.45923797782704,1137457.22149687,779487.128748296
,653544.644,257.9669,-0.019,5.433485e+04,0.5,244551.1,391251.9,5.38339562116066E-12,-3.3648790482296E-12,0.0215084046814759,0.0134437788649719,33.4320607351161,20.8966326503192,0.625047699448872,444748.037436259,711542.555597614
,653654.017,255.9806,-0.019,1.648255e+05,0.5,50216.87,187772.7,4.7991306970703E-12,-1.28345239924541E-12,0.0313133716182433,0.00837427118966183,29.803648149051,7.97051927477548,0.267434350147812,91325.9207531341,341489.119489168
,653767.507,253.9816,-0.019,5.000000e+05,0.5,8081.495,69593.98,4.51295780237461E-12,-5.24060355724754E-13,0.0352058388336398,0.0040882244485064,28.0264520688291,3.25452908803294,0.11612347792151,14697.251579735,126565.719894036
,653833.558,253.9816,-0.019,2.298591e+01,0.5,3355658,134128,8.23439441087637E-11,-2.0601076195882E-09,3.11926087646289E-06,7.80386847950444E-05,511.373849210001,12793.7175540702,25.018325778361,6102701.27514161,243929.243275743
,653947.018,251.9755,-0.019,6.972812e+01,0.5,3725071,418012.4,6.79048262120689E-11,-6.05126304584787E-10,2.94894760058058E-05,0.000262792184811798,421.703778411874,3757.96630806286,8.91138875306091,6774526.9457415,760210.01142101
,654061.289,249.9731,-0.019,2.115173e+02,0.5,3595089,1064219,5.69640642996377E-11,-1.92433024555021E-10,0.000227747983580417,0.000769366333942673,353.759261143425,1195.05104530633,3.37814773087118,6538137.74364002,1935420.90651965
,654174.311,247.9764,-0.019,6.416440e+02,0.5,2811708,1143984,3.07947587039543E-11,-7.56880073549786E-11,0.000742658445235912,0.00182532158818425,191.242166796553,470.039030545185,2.45782108840683,5113457.32995611,2080483.95144606
,654287.303,245.9878,-0.019,1.946446e+03,0.5,2443972,1017130,1.1868297765449E-11,-2.85172863118972E-11,0.00200304764228086,0.0048129465775274,73.7047171783723,177.098566605902,2.40281183329565,4444681.50234928,1849783.42488561
,654401.371,243.9795,-0.019,5.904585e+03,0.5,1856420,1321451,6.8596966894267E-12,-9.63673880316827E-12,0.00789426172015313,0.0110901314861669,42.6002122979666,59.8462493987224,1.4048345341598,3376141.63934417,2403230.81277566
,654511.632,241.9871,-0.019,1.791157e+04,0.5,721956.9,1164093,5.51270200439684E-12,-3.41891348003821E-12,0.0210956919872294,0.0130833020991063,34.2350815721501,21.2321982548444,0.620188335468043,1312972.68500762,2117054.78790849
,654623.75,239.9737,-0.019,5.433485e+04,0.5,154203.4,561628.1,4.8498492043066E-12,-1.33159868032132E-12,0.0308745451594955,0.00847706843202423,30.1186211388966,8.26951817925371,0.274564965677465,280438.973760488,1021393.8732807
,654733.996,237.9835,-0.019,1.648255e+05,0.5,25399.39,210312.2,4.52525132288463E-12,-5.46514292551562E-13,0.0350721061924887,0.00423565586449305,28.1027975119773,3.39397293213489,0.120769931558892,46192.099952027,382480.1368667
,654847.409,235.9846,-0.019,5.000000e+05,0.5,4063.311,72573.8,4.37231050527225E-12,-2.44799877800091E-13,0.0367132545996767,0.00205552652969345,27.1530016836348,1.52026062331216,0.0559886763542766,7389.66045437197,131984.910798977
,654916.174,235.9846,-0.019,2.298591e+01,0.5,11743730,1353217,6.70482961705106E-11,-5.81870525707637E-10,3.14702138663402E-05,0.000273110443253784,416.384540074965,3613.54284997496,8.67837900351533,21357503.0726966,2461001.4225059
,655029.29,233.9665,-0.019,6.972812e+01,0.5,11327010,3361906,5.49672878296166E-11,-1.85197033741855E-10,0.000237172022458603,0.000799085361134078,341.358843838444,1150.11396444353,3.36922269688683,20599643.4590598,6114064.07718135
,655142.953,231.9793,-0.019,2.115173e+02,0.5,9032024,3624226,2.87923901815703E-11,-7.17542336314863E-11,0.000775601792055695,0.00193289656889224,178.807021626971,445.609437905727,2.4921249392284,16425912.4088061,6591127.17434297
,655256.943,229.9808,-0.019,6.416440e+02,0.5,7874066,3426499,1.15255268765907E-11,-2.64855642190611E-11,0.00222443532421992,0.0051117337421196,71.5760352123843,164.481129362839,2.2979916235201,14320014.9177149,6231534.86337745
,655369.934,227.9818,-0.019,1.946446e+03,0.5,5676317,4414766,6.98080208824251E-12,-8.97561627663311E-12,0.00869405742385114,0.0111784465935414,43.3523032334063,55.7405343415572,1.28575716130821,10323122.0207804,8028827.16225903
,655481.397,225.9804,-0.019,5.904585e+03,0.5,2095526,3596520,5.595156228614E-12,-3.26003896853697E-12,0.0214853749111886,0.0125185350689398,34.7471402848815,20.2455528935239,0.582653787550187,3810987.05299896,6540740.20358222
,655592.111,223.9833,-0.019,1.791157e+04,0.5,454029.8,1700852,4.87670306565672E-12,-1.30179963780476E-12,0.0308228379587053,0.00822792750564033,30.2853894737558,8.08445962711126,0.266942567607293,825712.345957869,3093220.96269261
,655704.073,221.9689,-0.019,5.433485e+04,0.5,76739.33,637348.8,4.53015874084308E-12,-5.45449127017956E-13,0.0350371612601832,0.00421861354443346,28.1332736476331,3.38735802189636,0.120403976598057,139560.469822763,1159101.83173314
,655814.943,219.9722,-0.019,1.648255e+05,0.5,12283.78,220514.5,4.36528962163938E-12,-2.43168849887429E-13,0.036773463265486,0.00204846906934152,27.1094004652689,1.51013158430516,0.0557050896879797,22339.6543597587,401034.348654486
,655927.685,217.9820,-0.019,5.000000e+05,0.5,2144.529,74300.19,4.28053994163497E-12,-1.2354937504863E-13,0.0375865917490107,0.00108486312103528,26.5830864715413,0.767268560790058,0.0288630352089275,3900.10539300434,135124.575941965
,656000.631,217.9820,-0.019,2.298591e+01,0.5,38153980,11454210,4.99769338219639E-11,-1.66473194878087E-10,0.000266377409070366,0.000887303300543866,310.367657231653,1033.83484209416,3.33100056660389,69387983.6377031,20830973.2316999
,656113.451,215.9749,-0.019,6.972812e+01,0.5,31108940,12420850,2.52671826036778E-11,-6.32835327362345E-11,0.00087625237444323,0.00219463905782712,156.914713845478,393.00453818669,2.50457416360394,56575660.5131702,22588934.0133418
,656226.411,213.9855,-0.019,2.115173e+02,0.5,26988540,12800580,1.07949206813298E-11,-2.2759839679522E-11,0.00273938567499717,0.00577567734158047,67.0388114205078,141.34356752388,2.10838415134314,49082176.2742837,23279522.4926236
,656338.014,211.9909,-0.019,6.416440e+02,0.5,17661090,15822270,6.98002327299029E-12,-7.79122207030825E-12,0.0102715968390317,0.0114653331170467,43.347466620858,48.3851880458979,1.11621720524299,32118993.1939997,28774859.4477253
,656449.586,209.9789,-0.019,1.946446e+03,0.5,5995244,11467680,5.59973017671072E-12,-2.92751007558145E-12,0.0225834548056113,0.01180651377808,34.775545499978,18.1804759555089,0.522794846036862,10903132.3226578,20855470.18168
,656558.833,207.9881,-0.019,5.904585e+03,0.5,1287128,5216044,4.87102355506816E-12,-1.20198963168021E-12,0.0311603052098295,0.00768921836627863,30.250118474501,7.46461772405437,0.246763255831431,2340809.96539888,9486055.60220819
,656668.798,205.9832,-0.019,1.791157e+04,0.5,220274.6,1939872,4.522202877144E-12,-5.13501112383571E-13,0.0351543581197127,0.00399181604408768,28.08386599917,3.18895388428761,0.113551100278781,400598.059248382,3527909.97414263
,656779.356,203.9698,-0.019,5.433485e+04,0.5,36256.01,670331.6,4.35695526155998E-12,-2.35653240176461E-13,0.0368503343334083,0.00199311220013408,27.0576422717474,1.46345800911205,0.0540866788914621,65936.2779098904,1219085.35079788
,656890.414,201.9773,-0.019,1.648255e+05,0.5,6117.464,226003.9,4.26934995802584E-12,-1.15562583971447E-13,0.0376888871911215,0.00102016120337634,26.5135942331899,0.717668846564801,0.0270679576768366,11125.4053164634,411017.537757714
,657006.821,199.9861,-0.019,5.000000e+05,0.5,1065.251,75321.11,4.22519305682439E-12,-5.97560382338396E-14,0.0381030494222468,0.000538883607797306,26.2393702476744,0.37109802810534,0.0141427947623183,1937.29773297692,136981.251975643
,657079.144,199.9861,-0.019,2.298591e+01,0.5,113773100,46753670,2.13959341023269E-11,-5.20661105367225E-11,0.0010872964158271,0.00264589034074839,132.873416470052,323.34190020567,2.43345816488845,206911205.625488,85027640.3395549
,657190.263,197.9702,-0.019,6.972812e+01,0.5,96300000,52483080,9.95944742627291E-12,-1.82743617019062E-11,0.00370251822283451,0.00679366578445783,61.8503403195108,113.487771159179,1.83487706895251,175134096.739339,95447318.8982188
,657301.866,195.9701,-0.019,2.115173e+02,0.5,54757860,58722480,6.85382454835296E-12,-6.39109187969028E-12,0.0125668931026803,0.0117184453577494,42.5637450213929,39.6900742434095,0.932485480858438,99584302.7048721,106794480.717486
,657411.285,193.9779,-0.019,6.416440e+02,0.5,16853280,37231620,5.52917734837341E-12,-2.50283962991121E-12,0.0241702480304045,0.0109409141403424,34.337397050933,15.5431798823298,0.452660399950365,30649885.461009,67710551.8052161
,657521.812,191.9821,-0.019,1.946446e+03,0.5,3518377,16175640,4.82659892271115E-12,-1.04983757291159E-12,0.0318549030747142,0.00692878663937276,29.9742318201267,6.51972026013202,0.217510837283718,6398626.97698303,29417508.8326139
,657631.527,189.9812,-0.019,5.904585e+03,0.5,601142.1,5927666,4.50096090851287E-12,-4.56455726851232E-13,0.0354114884272313,0.00359118353113545,27.9519487418505,2.83468960055583,0.10141295072968,1093255.23048276,10780232.9250518
,657740.837,187.9801,-0.019,1.791157e+04,0.5,100659.3,2041029,4.34293013625964E-12,-2.14184270514922E-13,0.0369875251556386,0.0018241477171069,26.9705431852498,1.33013102589283,0.049317917579809,183062.051754041,3711877.15819103
,657853.002,185.9897,-0.019,5.433485e+04,0.5,18151.89,687932.4,4.25493943617703E-12,-1.12271485689797E-13,0.0378179082394206,0.000997869137130416,26.4241017500849,0.697230408563907,0.0263861536395146,33011.5769393753,1251094.69877181
,657970.783,183.9745,-0.019,1.648255e+05,0.5,3350.648,229577.9,4.20506962638637E-12,-6.13722319679388E-14,0.0382848949716114,0.000558761129737836,26.1143993564476,0.381134943628644,0.0145948194490846,6093.58993739847,417517.32240721
,658087.612,181.9741,-0.019,5.000000e+05,0.5,556.6208,76144.19,4.18013347361045E-12,-3.05571474092485E-14,0.0385194248303955,0.000281580420838866,25.9595404100184,0.189766548841832,0.00731008892470982,1012.28744583934,138478.130193132
,658153.179,181.9741,-0.019,2.298591e+01,0.5,352596800,235193100,9.0652901914502E-12,-1.35905020707526E-11,0.00546961585384129,0.0081999388897621,56.2974289072726,84.3999814660031,1.49918003546873,641243219.949962,427729295.200675
,658264.486,179.9722,-0.019,6.972812e+01,0.5,166120500,222131500,6.58995005974765E-12,-4.92827806457126E-12,0.0156706871360363,0.0117192851188684,40.9250269054841,30.6056814636937,0.747847558765866,302111772.766224,403975073.830265
,658373.063,177.9821,-0.019,2.115173e+02,0.5,45984320,122700900,5.37706562474787E-12,-2.01514989987364E-12,0.0262585826399476,0.00984086560784635,33.3927500770448,12.5145203109582,0.374767585241836,83628477.1274426,223147573.111152
,658483.667,175.9895,-0.019,6.416440e+02,0.5,9186463,50561180,4.74899502575221E-12,-8.62845113410264E-13,0.0328236123303237,0.00596372355627109,29.4922946973534,5.35845631020346,0.181690043626355,16706779.8518625,91952093.347613
,658593.554,173.9761,-0.019,1.946446e+03,0.5,1560613,18188750,4.46262092674968E-12,-3.82897353163775E-13,0.0358193473828675,0.00307333594541786,27.7138490945105,2.37787605948355,0.0858010033674662,2838178.06972658,33078611.6517929
,658703.566,171.9842,-0.019,5.904585e+03,0.5,266201.7,6225175,4.32202926465689E-12,-1.84819147686838E-13,0.0371887877066605,0.0015902715198291,26.8407442148577,1.14776720963833,0.0427621231531644,484122.474350743,11321291.8034197
,658816.698,169.9827,-0.019,1.791157e+04,0.5,48638.52,2092688,4.24373275444496E-12,-9.86333750906615E-14,0.0379236894933404,0.000881427202667396,26.3545058127488,0.612534767754916,0.0232421268722332,88455.4856379883,3805825.78024147
,658933.839,167.9777,-0.019,5.433485e+04,0.5,10251.81,698664.8,4.191592448647E-12,-6.15050441656195E-14,0.0384079035912731,0.000563575737773035,26.0307031437915,0.381959736337873,0.0146734313793968,18644.2521733471,1270612.9664753
,659050.606,165.9800,-0.019,1.648255e+05,0.5,1952.483,232103.3,4.15990796491196E-12,-3.49936842046416E-14,0.0387060360037461,0.000325600184463996,25.8339355905344,0.217318409792594,0.00841212942685434,3550.84472070524,422110.091336655
,659166.874,163.9890,-0.019,5.000000e+05,0.5,225.4741,76714.64,4.14923587593178E-12,-1.21951328301017E-14,0.0388080010946449,0.000114061659151553,25.7676595907633,0.0757344342010043,0.00293912739471892,410.054027431105,139515.567840951
,659224.656,163.9890,-0.019,2.298591e+01,0.5,482606200,834302500,6.21846270638458E-12,-3.59709896179141E-12,0.0194024152107329,0.0112234182154243,38.6180094328793,22.3387689524675,0.578454697187171,877682252.521338,1517287795.89691
,659335.339,161.9737,-0.019,6.972812e+01,0.5,120029600,406460200,5.16518462277568E-12,-1.5253032011447E-12,0.0286745041898638,0.00846771533377113,32.0769228510636,9.47246549365478,0.295304681737597,218289466.022681,739200830.607384
,659445.429,159.9819,-0.019,2.115173e+02,0.5,22621100,158558600,4.65081412012476E-12,-6.63518290983612E-13,0.0339323028712454,0.00484102417958237,28.8825698636325,4.12059327682143,0.142667127484728,41139417.609037,288359472.391009
,659554.755,157.9880,-0.019,6.416440e+02,0.5,3830984,55917540,4.41511679763084E-12,-3.02485442132379E-13,0.0363008864790215,0.00248702134047649,27.4188380937163,1.87850055699191,0.0685113114775793,6967143.53543988,101693331.877319
,659664.891,155.9716,-0.019,1.946446e+03,0.5,661322.7,19005950,4.29697924978192E-12,-1.49515805277282E-13,0.0374286702160077,0.00130235159224663,26.685178159964,0.928525754867736,0.0347955613899858,1202701.49239586,34564796.3231884
,659780.145,153.9798,-0.019,5.904585e+03,0.5,127084.4,6369784,4.22994920352293E-12,-8.43922739860863E-14,0.0380526724009017,0.000759193881686592,26.2689069558193,0.524094424416294,0.0199511317809207,231119.538978825,11584282.1107445
,659896.444,151.9876,-0.019,1.791157e+04,0.5,27251.82,2124004,4.18273387980624E-12,-5.36661469565883E-14,0.0384911980087873,0.00049385745023071,25.9756894995506,0.333278475284248,0.0128303995661025,49560.9852565219,3862778.00634209
,660014.178,149.9720,-0.019,5.433485e+04,0.5,6406.452,706222.9,4.14728496560758E-12,-3.76218075942972E-14,0.038823397224462,0.00035218375217718,25.7555440122257,0.233639629142883,0.00907143056391969,11650.9676461468,1284358.35605542
,660130.944,147.9749,-0.019,1.648255e+05,0.5,987.8945,233907.9,4.12803273214137E-12,-1.74344724222758E-14,0.0390069749071239,0.000164743371097708,25.635983444171,0.108271875582602,0.0042234336676957,1796.61485909928,425391.991554472
,660247.181,145.9825,-0.019,5.000000e+05,0.5,5.241352,77085.39,4.12931535680342E-12,-2.80769096504699E-16,0.0389955541667292,2.65146775313577E-06,25.6439488230173,0.00174363731507902,6.79941036816445E-05,9.5320814975382,140189.825020246
,660296.43,145.9825,-0.019,2.298591e+01,0.5,293325700,1340262000,4.93005798561957E-12,-1.07897762502589E-12,0.031168934307601,0.00682153897822297,30.6167351615414,6.70068633817398,0.218856984679115,533451002.283846,2437441067.1242
,660405.99,143.9741,-0.019,6.972812e+01,0.5,52236570,496636900,4.54567178012395E-12,-4.78116511558986E-13,0.0350361901851423,0.00368512770827037,28.2296130044111,2.96920779704011,0.105180605790669,94999008.3459113,903198908.503899
,660515.565,141.9887,-0.019,2.115173e+02,0.5,8851794,171905600,4.36545593949904E-12,-2.24786840524811E-13,0.0367886250538486,0.0018943264822083,27.1104333354454,1.39597529769883,0.0514921794287097,16098140.6719907,312632730.84563
,660625.982,139.9917,-0.019,6.416440e+02,0.5,1572200,57979420,4.274948505839E-12,-1.15921719135515E-13,0.0376394301955971,0.00102065029545859,26.5483624359544,0.719899154248308,0.0271165182404377,2859250.53887424,105443129.295647
,660743.233,137.9832,-0.019,1.946446e+03,0.5,313010.9,19409390,4.2116620409542E-12,-6.79205336146531E-14,0.0382231699759222,0.000616416530092722,26.1553396884857,0.421801324807149,0.0161267767817536,569251.103230193,35298504.5265998
,660859.999,135.9837,-0.019,5.904585e+03,0.5,72891.03,6459876,4.17208569523139E-12,-4.70763871587755E-14,0.038590876107957,0.000435446238923376,25.9095619513493,0.292354629946869,0.0112836577668054,132561.834885255,11748126.1506556
,660976.938,133.9843,-0.019,1.791157e+04,0.5,17814.95,2145439,4.14134047523902E-12,-3.43881944438221E-14,0.0388796430537676,0.000322842503105759,25.7186274307543,0.213558186342057,0.00830363855602513,32398.8076501193,3901760.34656647
,661093.221,131.9908,-0.019,5.433485e+04,0.5,3964.995,711581.4,4.11626511870458E-12,-2.29361962163964E-14,0.0391179716060451,0.000217968825250506,25.5629039986293,0.142438780074978,0.00557208915241461,7210.85999897192,1294103.48645394
,661211.002,129.9753,-0.019,1.648255e+05,0.5,359.1936,235034.5,4.10830935759204E-12,-6.27856092644769E-15,0.039194849100045,5.98998825691629E-05,25.513496987251,0.0389912324847621,0.00152825904282137,653.240360234179,427440.860436991
,661327.394,127.9823,-0.019,5.000000e+05,0.5,-119.5974,77323.98,4.11656415893051E-12,6.36711108690053E-15,0.0391162508288157,-6.05013075746257E-05,25.5647611036423,-0.0395411482908246,-0.00154670517477243,-217.503454012185,140623.732020672
,661368.11,127.9823,-0.019,2.298591e+01,0.5,112694200,1548559000,4.44773794547926E-12,-3.23677864114592E-13,0.036013058448605,0.00262079960235211,27.6214225353707,2.01011011881728,0.0727735914485661,204949085.407709,2816256300.23441
,661476.453,125.9898,-0.019,6.972812e+01,0.5,19451710,528101100,4.31627773720541E-12,-1.58982783454865E-13,0.0372558917321344,0.00137225770172582,26.8050259751798,0.987317753762801,0.0368333071072944,35375468.9603901,960420655.613202
,661589.975,123.9830,-0.019,2.115173e+02,0.5,3627482,177063700,4.24773917714777E-12,-8.70229042192067E-14,0.0378924832579458,0.000776298591713038,26.379386571392,0.540431211811152,0.020486875627246,6597048.63456086,322013407.734427
,661707.1,121.9736,-0.019,6.416440e+02,0.5,759753.9,59030530,4.20121936377429E-12,-5.40718979887702E-14,0.0383217961363549,0.000493221627344369,26.0904883860208,0.335798277674011,0.0128705247945428,1381711.45400509,107354709.77772
,661823.883,119.9752,-0.019,1.946446e+03,0.5,182255.3,19644970,4.16188030779497E-12,-3.86116519425209E-14,0.0386871008043989,0.000358917787262387,25.846184269936,0.239786778395308,0.00927745371970535,331455.008737874,35726937.4498589
,661940.166,117.9828,-0.019,5.904585e+03,0.5,48249.96,6515747,4.13661084433446E-12,-3.06321451361914E-14,0.038924645802457,0.000288242100711203,25.6892553914722,0.190232301080493,0.00740513098498146,87748.8386532631,11849734.8434793
,662056.964,115.9851,-0.019,1.791157e+04,0.5,11573.69,2160778,4.1121073406425E-12,-2.20255184046305E-14,0.0391576163938633,0.000209738396670779,25.5370832901998,0.136783272277371,0.00535626056910983,21048.2631785163,3929656.31655489
,662174.651,113.9670,-0.019,5.433485e+04,0.5,2196.082,714991.1,4.09672372777398E-12,-1.25830115053703E-14,0.0393054140374874,0.000120725855566976,25.4415476996658,0.0781432453570085,0.00307148158907153,3993.86124024425,1300304.47014711
,662291.012,111.9780,-0.019,1.648255e+05,0.5,-13.35421,235754.4,4.09577377061741E-12,2.32003402885871E-16,0.039314901142903,-2.22697623455412E-06,25.4356482585715,-0.00144079172363739,-5.6644584364067E-05,-24.2863707789974,428750.092381359
,662407.202,109.9864,-0.019,5.000000e+05,0.5,-181.4306,77497.08,4.10735658136609E-12,9.61584835159208E-15,0.0392038177520195,-9.1781163587577E-05,25.5075800391212,-0.0597165151389675,-0.00234112820766924,-329.955184339318,140938.536923534
,662436.031,109.9864,-0.019,2.298591e+01,0.5,41437780,1618159000,4.27617041167733E-12,-1.09504077634889E-13,0.037631665726741,0.000963670866347641,26.5559507376648,0.680044201069357,0.0256079779551948,75360001.7776059,2942832968.28278
,662552.844,107.9879,-0.019,6.972812e+01,0.5,8145460,540616400,4.22111771035308E-12,-6.35995235530639E-14,0.0381388072606103,0.000574636894087953,26.214061457399,0.394966910065594,0.0150669864991147,14813580.2661102,983181359.25725
,662670.453,105.9730,-0.019,2.115173e+02,0.5,1785848,179787700,4.18472374120483E-12,-4.15672513958584E-14,0.0384754323570251,0.000382180059725602,25.9880469727541,0.258141695511979,0.00993309330949781,3247797.26265582,326967356.639079
,662787.236,103.9723,-0.019,6.416440e+02,0.5,447866.8,59645710,4.15834270037694E-12,-3.12241004176357E-14,0.038721162405761,0.00029074887529964,25.8242149564432,0.19390847246272,0.00750878478938385,814504.127492609,108473494.758324
,662903.488,101.9808,-0.019,1.946446e+03,0.5,127948.8,19800850,4.12929934608993E-12,-2.66826371682524E-14,0.0389940773624384,0.000251971274244851,25.6438493929951,0.16570499535194,0.0064617832062765,232691.562999817,36010425.5391603
,663019.272,99.9897,-0.019,5.904585e+03,0.5,33695.07,6557589,4.1103332414356E-12,-2.11202572002453E-14,0.0391746071698438,0.000201292141183351,25.5260657472568,0.131161402792767,0.00513833209126098,61278.8748600083,11925829.971992
,663136.522,97.9763,-0.019,1.791157e+04,0.5,6893.829,2170445,4.0938684698025E-12,-1.30030612060246E-14,0.0393328017565797,0.000124929961091278,25.4238159250324,0.0807518455960183,0.00317622837713004,12537.3262200463,3947237.01554948
,663252.711,95.9920,-0.019,5.433485e+04,0.5,1136.848,716981.5,4.08537915354919E-12,-6.47778934317565E-15,0.0394148328765474,6.24962763000679E-05,25.3710954198804,0.0402284843972965,0.001585602975809,2067.50620571053,1303924.27187244
,663369.572,93.9922,-0.019,1.648255e+05,0.5,-221.7606,236203.8,4.08797758463937E-12,3.83800921897182E-15,0.0393898440350553,-3.69812655305303E-05,25.3872322435761,-0.0238348741835431,-0.000938852804230923,-403.300543856427,429567.384832809
,663486.994,91.9774,-0.019,5.000000e+05,0.5,-215.4045,77615,4.1011071892922E-12,1.13817811448289E-14,0.0392634705052499,-0.0001089677025375,25.4687699515714,-0.0706833428722962,-0.002775294723958,-391.741147882544,141152.989807101
,663515.823,91.9774,-0.019,2.298591e+01,0.5,17931230,1648802000,4.19895318847172E-12,-4.56649102692256E-14,0.038344294790303,0.000417006025631171,26.0764149432194,0.283589050669701,0.0108753082541142,32610277.9800139,2998561256.19954
,663632.574,89.9830,-0.019,6.972812e+01,0.5,4174288,547286700,4.1703749246199E-12,-3.18084579861739E-14,0.0386093762001956,0.000294483048391204,25.8989376927936,0.197537460391009,0.00762724180945746,7591486.58784904,995312168.867639
,663749.855,87.9772,-0.019,2.115173e+02,0.5,1088592,181336600,4.1492394482334E-12,-2.49085340159201E-14,0.0388069044053232,0.000232963922784477,25.7676817755354,0.154687427906962,0.00600315656078254,1979746.38253033,329784233.092241
,663866.466,85.9745,-0.019,6.416440e+02,0.5,322010.8,60055350,4.13009259040964E-12,-2.21451447558274E-14,0.0389870949760648,0.000209044916779581,25.648775613199,0.137526178004569,0.00536190031362735,585618.593959626,109218478.469521
,663983.935,83.9695,-0.019,1.946446e+03,0.5,94888.23,19913080,4.10610485054201E-12,-1.95660852797431E-14,0.039215093394699,0.000186864653861064,25.4998065177455,0.121509656256658,0.00476512071462576,172566.609057577,36214530.4163883
,664099.204,81.9846,-0.019,5.904585e+03,0.5,23841.94,6588260,4.09125242534087E-12,-1.48056383399914E-14,0.039357833714921,0.000142430187934466,25.4075697184591,0.0919462426761116,0.00361885232216093,43359.6742099015,11981609.1815568
,664216.969,79.9749,-0.019,1.791157e+04,0.5,3957.757,2176421,4.08265524394925E-12,-7.4241874023118E-15,0.0394410988216043,7.17224677343658E-05,25.3541793472767,0.0461058227203927,0.00181847032352656,7197.696752947,3958105.15015087
,664333.752,77.9773,-0.019,5.433485e+04,0.5,532.5766,718351.7,4.07759462088414E-12,-3.02307557616801E-15,0.0394901572803255,2.92774885864695E-05,25.3227517744999,0.0187739585535986,0.000741386983562508,968.559935467376,1306416.15909313
,664450.596,75.9749,-0.019,1.648255e+05,0.5,-316.1355,236557.3,4.08186501284701E-12,5.45500999871446E-15,0.039448794440876,-5.27194229684036E-05,25.3492718398104,-0.0338768016362817,-0.00133640137083066,-574.933595428238,430210.270639635
,664567.426,73.9724,-0.019,5.000000e+05,0.5,-229.5675,77720.1,4.09555712134571E-12,1.20973443093168E-14,0.0393166379438906,-0.00011613240694729,25.4343028193507,-0.0751271461627211,-0.00295377257620615,-417.498408652214,141344.127850375
,664596.254,73.9724,-0.019,2.298591e+01,0.5,9350829,1665929000,4.1561453720345E-12,-2.33283679394716E-14,0.0387425977623237,0.00021746149247133,25.8105690682773,0.144874251994023,0.00561298170570294,17005700.8377883,3029708937.14299
,664713.068,71.9797,-0.019,6.972812e+01,0.5,2570970,551237100,4.1406390417111E-12,-1.93119417344514E-14,0.0388880646458334,0.000181373945190733,25.7142713755881,0.119931369420701,0.00466400030041519,4675643.91167122,1002496485.95756
,664830.474,69.9704,-0.019,2.115173e+02,0.5,800961.8,182369900,4.12579913487077E-12,-1.81203559441801E-14,0.0390280355742213,0.000171409676838077,25.6221123180522,0.112531361820505,0.00439196270875841,1456653.38905208,331663423.768885
,664946.149,67.9834,-0.019,6.416440e+02,0.5,250829.6,60340920,4.11059362443867E-12,-1.70872196608952E-14,0.0391724830341198,0.00016283507527653,25.5276827824862,0.106115360210913,0.00415687397540508,456166.307699789,109737824.72088
,665062.963,65.9864,-0.019,1.946446e+03,0.5,69599.59,19987700,4.09081883064734E-12,-1.42447261754646E-14,0.039362043553545,0.000137063398634604,25.4048770008606,0.0884628558193453,0.00348212100441772,126575.922409952,36350236.6084827
,665179.854,63.9815,-0.019,5.904585e+03,0.5,17243.95,6603110,4.08207706266275E-12,-1.06602998836463E-14,0.0394465466422594,0.000103014227836851,25.3505887154067,0.0662027869108704,0.00261148913163646,31360.369755642,12008615.8413343
,665297.136,61.9718,-0.019,1.791157e+04,0.5,2165.034,2180238,4.07551709020754E-12,-4.0470962655822E-15,0.0395102704911489,3.92347436208956E-05,25.3098498559624,0.0251333503374649,0.000993026449405982,3937.39640706083,3965046.86196036
,665413.403,59.9852,-0.019,5.433485e+04,0.5,222.372,719283.1,4.0723163909711E-12,-1.25898848519175E-15,0.0395413594038687,1.22245207392709E-05,25.2899728157451,0.00781859303378999,0.000309157826730532,404.412454414541,1308110.03134342
,665530.232,57.9837,-0.019,1.648255e+05,0.5,-367.241,236809.2,4.07752050479603E-12,6.32337218191607E-15,0.0394908018163392,-6.12418839717131E-05,25.3222914974306,-0.0392695201529667,-0.00155078856733607,-667.875605614243,430668.383609195
,665647.686,55.9753,-0.019,5.000000e+05,0.5,-236.4366,77793.12,4.09171075634471E-12,1.24359349440358E-14,0.039353576919814,-0.000119607311350403,25.4104160539387,-0.0772298678389384,-0.00303929961929795,-429.990761963867,141476.924234008
,665676.53,55.9753,-0.019,2.298591e+01,0.5,5709658,1675811000,4.13171942847011E-12,-1.40771870387053E-14,0.0389724120887969,0.000132782959690619,25.6588786323102,0.0874224012457246,0.00340710139747263,10383756.9732143,3047680641.64952
,665793.406,53.9758,-0.019,6.972812e+01,0.5,1919648,553847900,4.12116049843563E-12,-1.4284025467102E-14,0.0390722484737676,0.000135425201825575,25.5933053742678,0.0887069129901955,0.0034660201835197,3491129.99519708,1007244565.9136
,665910.204,51.9725,-0.019,2.115173e+02,0.5,627288.6,183101100,4.10935411205336E-12,-1.40782932918164E-14,0.0391845158903912,0.000134242776884253,25.5199851402797,0.0874292713187788,0.00342591388036445,1140806.04730929,332993206.235508
,666027.049,49.9776,-0.019,6.416440e+02,0.5,200227.1,60547080,4.09662323055628E-12,-1.35473913729104E-14,0.0393063192285682,0.000129984638578945,25.4409235900289,0.0841322546314882,0.00330696542260998,364139.068548674,110112753.541064
,666143.27,47.9802,-0.019,1.946446e+03,0.5,48760.16,20040180,4.08013136131744E-12,-9.92744865559371E-15,0.0394653931158103,9.60240318594846E-05,25.3385054857638,0.0616516209757957,0.00243311986219685,88676.7038262269,36445678.3259997
,666260.068,45.9800,-0.019,5.904585e+03,0.5,8964.219,6616919,4.07357838724417E-12,-5.51864829793497E-15,0.0395290407037824,5.35516571577526E-05,25.2978100877975,0.0342720093516977,0.00135474213905293,16302.6001821248,12033729.306982
,666377.053,43.9822,-0.019,1.791157e+04,0.5,795.3481,2182894,4.07056174611183E-12,-1.48312907117924E-15,0.0395584025200488,1.44132973398415E-05,25.2790760885432,0.00921055494988684,0.00036435488851039,1446.44414420404,3969877.14400543
,666493.835,41.9783,-0.019,5.433485e+04,0.5,63.71154,719969.9,4.06843204820735E-12,-3.60023483171511E-16,0.0395791150603531,3.50243304939871E-06,25.2658502001448,0.00223582433885157,8.84919494551092E-05,115.867736342391,1309359.06662526
,666610.259,39.9874,-0.019,1.648255e+05,0.5,-391.8275,236979.2,4.07459410433012E-12,6.73703861526417E-15,0.0395191513750082,-6.53419805847561E-05,25.3041179123932,-0.0418384789100404,-0.00165342570149617,-712.589359191416,430977.550758164
,666727.01,37.9867,-0.019,5.000000e+05,0.5,-239.9023,77844.49,4.08900955017042E-12,1.26015700765443E-14,0.0393795637069023,-0.000121360521551138,25.393640974559,-0.0782584981309654,-0.00308181478226654,-436.293588953167,141570.347271906
,666755.839,37.9867,-0.019,2.298591e+01,0.5,4371649,1682859000,4.11443532563443E-12,-1.06882793370535E-14,0.0391363193315599,0.000101666420816892,25.5515405846507,0.0663765454178559,0.00259775120791463,7950413.28012913,3060498347.9197
,666873.323,35.9736,-0.019,6.972812e+01,0.5,1613492,555780800,4.10684260932849E-12,-1.19226099487615E-14,0.0392086085630177,0.000113826847288644,25.5043881606885,0.0740420076803043,0.00290310856366395,2934345.42072845,1010759796.39738
,666989.996,33.9755,-0.019,2.115173e+02,0.5,525605.4,183668800,4.09666708474974E-12,-1.17234410076546E-14,0.0393060064203278,0.000112482083113512,25.4411959341334,0.0728051251243464,0.00286170215082801,955881.900003313,334025642.650034
,667106.966,31.9749,-0.019,6.416440e+02,0.5,147748.6,60696220,4.08657766942529E-12,-9.94767267959767E-15,0.0394031388348935,9.59163288662976E-05,25.3785384648248,0.0617772165750028,0.00243423066543518,268700.078977175,110383984.062224
,667223.811,29.9758,-0.019,1.946446e+03,0.5,32087.28,20071180,4.07384329132826E-12,-6.5127486458181E-15,0.0395264418282764,6.31899074368133E-05,25.2994551999259,0.0404455892900905,0.00159867431810188,58354.8992691823,36502055.8649293
,667339.719,27.9903,-0.019,5.904585e+03,0.5,4916.591,6622786,4.06997490839872E-12,-3.02144777210965E-15,0.0395640897774992,2.93713926017305E-05,25.2754316983763,0.0187638495354299,0.000742375036729256,8941.46130656037,12044399.210882
,667456.424,25.9859,-0.019,1.791157e+04,0.5,469.0331,2184228,4.06807603514406E-12,-8.73563709374354E-16,0.0395825772664917,8.49981729072794E-06,25.2636392813879,0.0054250211284862,0.000214736327892509,852.997801758589,3972303.19680969
,667574.329,23.9735,-0.019,5.433485e+04,0.5,-24.10422,720370.6,4.06616904488152E-12,1.36057514305851E-16,0.0396011428581883,-1.32508830830298E-06,25.2517964560106,-0.000844946833159072,-3.346086028497E-05,-43.8366645618516,1310087.79178168
,667690.129,21.9879,-0.019,1.648255e+05,0.5,-398.8896,237121.6,4.07214677381227E-12,6.85022789044637E-15,0.0395428982994463,-6.65196712805026E-05,25.2889194562013,-0.0425414089914894,-0.00168221536966687,-725.432708148663,431236.523711182
,667807.519,19.9804,-0.019,5.000000e+05,0.5,-238.9547,77898.73,4.08616277888648E-12,1.25343224591721E-14,0.039407002354589,-0.000120881154616258,25.3759619041059,-0.0778408757627635,-0.00306750443813397,-434.570254892209,141668.98977873
,667836.364,19.9804,-0.019,2.298591e+01,0.5,3588154,1687771000,4.10247003185451E-12,-8.72173668979909E-15,0.0392505520750973,8.34455772912727E-05,25.477233501071,0.0541638867451817,0.0021259720661156,6525525.54259238,3069431459.89461
,667899.638,20.0069,-0.019,6.972812e+01,0.5,1323158,557184100,4.09651071546538E-12,-9.72807896932762E-15,0.0393076070177978,9.33446856908791E-05,25.4402248467789,0.0604134917486236,0.00237472318395302,2406335.21467737,1013311880.2806
,668018.932,18.9900,-0.019,2.115173e+02,0.5,413877.7,184005500,4.08918365292748E-12,-9.19767031502441E-15,0.0393780618394394,8.85718180411181E-05,25.394722190646,0.0571195383420796,0.00224926809252984,752690.520769005,334637975.468021
,668135.792,17.9903,-0.019,6.416440e+02,0.5,111378.6,60771260,4.08154206220279E-12,-7.48045113313859E-15,0.039451853755496,7.23054325135251E-05,25.3472662458857,0.0464552327579518,0.00183275120509267,202556.495400749,110520454.07904
,668252.7,16.9904,-0.019,1.946446e+03,0.5,24521.12,20086000,4.07084183538627E-12,-4.96971030302335E-15,0.0395556270514619,4.82897678783303E-05,25.280815504015,0.0308629846993833,0.00122080653191277,44594.8515289402,36529007.9657982
,668368.967,15.9951,-0.019,5.904585e+03,0.5,6174.12,6627172,4.06728002589343E-12,-3.78922939580701E-15,0.0395902914542202,3.68837884807169E-05,25.2586958903602,0.0235319408445398,0.000931637205130635,11228.4416340632,12052375.7233254
,668486.217,14.9909,-0.019,1.791157e+04,0.5,469.4835,2185210,4.06624790371279E-12,-8.73616859570816E-16,0.0396003730693454,8.50797943900222E-06,25.2522861865491,0.0054253512027964,0.000214845941579985,853.816912840327,3974089.09175256
,668602.547,13.9946,-0.019,5.433485e+04,0.5,-127.8272,720682.4,4.06440971181102E-12,7.20903012358301E-16,0.0396182835304245,-7.02708190528904E-06,25.2408706139947,-0.00447696491013131,-0.000177369670745394,-232.47041755679,1310654.84070549
,668719.33,12.9937,-0.019,1.648255e+05,0.5,-394.5649,237210.6,4.07061918555087E-12,6.7708755506076E-15,0.0395577401272201,-6.57984751841722E-05,25.2794327999852,-0.0420486136571589,-0.00166335273381544,-717.567677741928,431398.381806819
,668836.58,11.9901,-0.019,5.000000e+05,0.5,-242.4568,77921.41,4.08497233825575E-12,1.27106185735346E-14,0.0394184755944403,-0.000122652778658729,25.3685690081962,-0.0789357130768863,-0.00311155560455079,-440.939280023994,141710.236313663
,668865.409,11.9901,-0.019,2.298591e+01,0.5,3275337,1689646000,4.09792064415534E-12,-7.94371786093999E-15,0.0392941567970298,7.61707515308611E-05,25.448980811399,0.049332220159646,0.00193847527825355,5956627.07177504,3072841391.68471
,668982.301,10.9907,-0.019,6.972812e+01,0.5,1205512,557696300,4.09275235092007E-12,-8.84686176340485E-15,0.0393437411363316,8.50451259309795E-05,25.4168845833865,0.0549409407376155,0.00216159225011893,2192380.63580928,1014243382.71414
,669099.145,9.9800,-0.019,2.115173e+02,0.5,383693.5,184122700,4.08658368474723E-12,-8.51603630102948E-15,0.0394031432030268,8.21122540923557E-05,25.3785758212858,0.0528864424749611,0.00208390111594062,697796.620428407,334851118.937781
,669168.347,10.0013,-0.019,6.416440e+02,0.5,109103.1,60801020,4.07954485535201E-12,-7.3204526882601E-15,0.0394711735321102,7.08282096746267E-05,25.3348631558224,0.0454616075252685,0.00179442877767511,198418.202180288,110574576.516412
,669390.883,8.9999,-0.019,1.946446e+03,0.5,24804.39,20095360,4.06894558693667E-12,-5.02243867376131E-15,0.039574059824,4.88476152583396E-05,25.2690393876385,0.0311904393798541,0.00123433419456034,45110.0149306365,36546030.3452943
,669613.668,7.9991,-0.019,5.904585e+03,0.5,3893.222,6628750,4.06631392056704E-12,-2.38824255168137E-15,0.0395997183228626,2.32578532254756E-05,25.25269616561,0.014831507036963,0.00058732370356402,7080.33144730761,12055245.52192
,669874.065,7.0040,-0.019,1.791157e+04,0.5,273.248,2185795,4.0651597487227E-12,-5.08188906562134E-16,0.0396109744386626,4.95179993705525E-06,25.2455285067726,0.00315596392773275,0.000125010808424395,496.937088949438,3975152.99047107
,670123.245,5.9960,-0.019,5.433485e+04,0.5,-28.58931,720894.6,4.06321344789575E-12,1.61139324469986E-16,0.0396299488628444,-1.57164846750691E-06,25.2334415542181,-0.00100071034373183,-3.96580998109849E-05,-51.9933850804876,1311040.75405262
,670350.882,5.0094,-0.019,1.648255e+05,0.5,-407.0503,237280.8,4.06941416797925E-12,6.98099575650539E-15,0.0395694468273294,-6.78805668300953E-05,25.2719493780938,-0.0433535059555509,-0.00171547929710284,-740.274004340363,431526.04965304
,671454.994,3.9996,-0.019,5.000000e+05,0.5,-247.6783,77937.49,4.08412782564364E-12,1.29789891467908E-14,0.0394266100607899,-0.000125294203785872,25.3633244007167,-0.0806023528589134,-0.00317790962988415,-450.435258073053,141739.479888694
,671483.823,3.9996,-0.019,2.298591e+01,0.5,2782418,1691266000,4.09399970353018E-12,-6.73532044462375E-15,0.0393318312767795,6.47075003680523E-05,25.4246309150987,0.0418278086956913,0.00164516876706562,5060189.64881909,3075787572.75135
,671812.252,2.9976,-0.019,6.972812e+01,0.5,1002866,558026000,4.09034012004724E-12,-7.35102492505958E-15,0.0393670004469145,7.07490802761795E-05,25.4019041036442,0.0456514677825142,0.00179716715708587,1823842.48245684,1014842985.12011
,672369.098,1.9988,-0.019,2.115173e+02,0.5,312069,184208700,4.08468183032911E-12,-6.91988257942744E-15,0.0394215476165807,6.67842666668769E-05,25.3667648906223,0.0429739797992798,0.00169410565299033,567538.135361877,335007521.142553
,672377.974,1.9988,-0.019,1.000008e+01,0.5,7411253,3883983000,4.09771009811912E-12,-7.81907805925403E-15,0.0392961803680731,7.49833185782283E-05,25.4476732746015,0.0485581798116547,0.00190815793992919,13478329.178211,7063529122.07631